Workbook

Sheet RESUMEN PRE FACTURA
A1: PREFACTURA ATM SERVICIOS JUNIO 2026
D2: SOLO LLENADO POR BANCO
A3: ITEM | B3: (OT) | C3: TICKET BCM | D3: SERIE | E3: ESTADO ATM | F3: TIPO DE MÁQUINA | G3: ATM | H3: NOMBRE | I3: SERVICIO | J3: TOTAL | K3: FECHA EJECUCIÓN | L3: SOLICITADO POR | M3: CATEGORIA | N3: OBSERVACIONES
A4: 1 | B4: {=INDIRECT("'"&$A4&"'!B7")} -> 0 | C4: {=INDIRECT("'"&$A4&"'!B6")} -> 0 | F4: {=INDIRECT("'"&$A4&"'!B8")} -> 0 | G4: {=INDIRECT("'"&$A4&"'!B4")} -> 0 | H4: {=INDIRECT("'"&$A4&"'!B5")} -> 0 | I4: {=INDIRECT("'"&$A4&"'!B1")} -> 0 | J4: {=INDIRECT("'"&$A4&"'!G24")} -> 0 | K4: {=INDIRECT("'"&$A4&"'!B9")} -> 0 | L4: {=INDIRECT("'"&$A4&"'!B2")} -> 0 | M4: {=INDIRECT("'"&$A4&"'!B3")} -> 0
A5: 2 | B5: {=INDIRECT("'"&$A5&"'!B7")} -> 0 | C5: {=INDIRECT("'"&$A5&"'!B6")} -> 0 | F5: {=INDIRECT("'"&$A5&"'!B8")} -> 0 | G5: {=INDIRECT("'"&$A5&"'!B4")} -> 0 | H5: {=INDIRECT("'"&$A5&"'!B5")} -> 0 | I5: {=INDIRECT("'"&$A5&"'!B1")} -> 0 | J5: {=INDIRECT("'"&$A5&"'!G24")} -> 0 | K5: {=INDIRECT("'"&$A5&"'!B9")} -> 0 | L5: {=INDIRECT("'"&$A5&"'!B2")} -> 0 | M5: {=INDIRECT("'"&$A5&"'!B3")} -> 0
A6: 3 | B6: {=INDIRECT("'"&$A6&"'!B7")} -> 0 | C6: {=INDIRECT("'"&$A6&"'!B6")} -> 0 | F6: {=INDIRECT("'"&$A6&"'!B8")} -> 0 | G6: {=INDIRECT("'"&$A6&"'!B4")} -> 0 | H6: {=INDIRECT("'"&$A6&"'!B5")} -> 0 | I6: {=INDIRECT("'"&$A6&"'!B1")} -> 0 | J6: {=INDIRECT("'"&$A6&"'!G24")} -> 0 | K6: {=INDIRECT("'"&$A6&"'!B9")} -> 0 | L6: {=INDIRECT("'"&$A6&"'!B2")} -> 0 | M6: {=INDIRECT("'"&$A6&"'!B3")} -> 0
A7: 4 | B7: {=INDIRECT("'"&$A7&"'!B7")} -> 0 | C7: {=INDIRECT("'"&$A7&"'!B6")} -> 0 | F7: {=INDIRECT("'"&$A7&"'!B8")} -> 0 | G7: {=INDIRECT("'"&$A7&"'!B4")} -> 0 | H7: {=INDIRECT("'"&$A7&"'!B5")} -> 0 | I7: {=INDIRECT("'"&$A7&"'!B1")} -> 0 | J7: {=INDIRECT("'"&$A7&"'!G24")} -> 0 | K7: {=INDIRECT("'"&$A7&"'!B9")} -> 0 | L7: {=INDIRECT("'"&$A7&"'!B2")} -> 0 | M7: {=INDIRECT("'"&$A7&"'!B3")} -> 0
A8: 5 | B8: {=INDIRECT("'"&$A8&"'!B7")} -> 0 | C8: {=INDIRECT("'"&$A8&"'!B6")} -> 0 | F8: {=INDIRECT("'"&$A8&"'!B8")} -> 0 | G8: {=INDIRECT("'"&$A8&"'!B4")} -> 0 | H8: {=INDIRECT("'"&$A8&"'!B5")} -> 0 | I8: {=INDIRECT("'"&$A8&"'!B1")} -> 0 | J8: {=INDIRECT("'"&$A8&"'!G24")} -> 0 | K8: {=INDIRECT("'"&$A8&"'!B9")} -> 0 | L8: {=INDIRECT("'"&$A8&"'!B2")} -> 0 | M8: {=INDIRECT("'"&$A8&"'!B3")} -> 0
A9: 6 | B9: {=INDIRECT("'"&$A9&"'!B7")} -> 0 | C9: {=INDIRECT("'"&$A9&"'!B6")} -> 0 | F9: {=INDIRECT("'"&$A9&"'!B8")} -> 0 | G9: {=INDIRECT("'"&$A9&"'!B4")} -> 0 | H9: {=INDIRECT("'"&$A9&"'!B5")} -> 0 | I9: {=INDIRECT("'"&$A9&"'!B1")} -> 0 | J9: {=INDIRECT("'"&$A9&"'!G24")} -> 0 | K9: {=INDIRECT("'"&$A9&"'!B9")} -> 0 | L9: {=INDIRECT("'"&$A9&"'!B2")} -> 0 | M9: {=INDIRECT("'"&$A9&"'!B3")} -> 0
A10: 7 | B10: {=INDIRECT("'"&$A10&"'!B7")} -> 0 | C10: {=INDIRECT("'"&$A10&"'!B6")} -> 0 | F10: {=INDIRECT("'"&$A10&"'!B8")} -> 0 | G10: {=INDIRECT("'"&$A10&"'!B4")} -> 0 | H10: {=INDIRECT("'"&$A10&"'!B5")} -> 0 | I10: {=INDIRECT("'"&$A10&"'!B1")} -> 0 | J10: {=INDIRECT("'"&$A10&"'!G24")} -> 0 | K10: {=INDIRECT("'"&$A10&"'!B9")} -> 0 | L10: {=INDIRECT("'"&$A10&"'!B2")} -> 0 | M10: {=INDIRECT("'"&$A10&"'!B3")} -> 0
A11: 8 | B11: {=INDIRECT("'"&$A11&"'!B7")} -> 0 | C11: {=INDIRECT("'"&$A11&"'!B6")} -> 0 | F11: {=INDIRECT("'"&$A11&"'!B8")} -> 0 | G11: {=INDIRECT("'"&$A11&"'!B4")} -> 0 | H11: {=INDIRECT("'"&$A11&"'!B5")} -> 0 | I11: {=INDIRECT("'"&$A11&"'!B1")} -> 0 | J11: {=INDIRECT("'"&$A11&"'!G24")} -> 0 | K11: {=INDIRECT("'"&$A11&"'!B9")} -> 0 | L11: {=INDIRECT("'"&$A11&"'!B2")} -> 0 | M11: {=INDIRECT("'"&$A11&"'!B3")} -> 0
A12: 9 | B12: {=INDIRECT("'"&$A12&"'!B7")} -> 0 | C12: {=INDIRECT("'"&$A12&"'!B6")} -> 0 | F12: {=INDIRECT("'"&$A12&"'!B8")} -> 0 | G12: {=INDIRECT("'"&$A12&"'!B4")} -> 0 | H12: {=INDIRECT("'"&$A12&"'!B5")} -> 0 | I12: {=INDIRECT("'"&$A12&"'!B1")} -> 0 | J12: {=INDIRECT("'"&$A12&"'!G24")} -> 0 | K12: {=INDIRECT("'"&$A12&"'!B9")} -> 0 | L12: {=INDIRECT("'"&$A12&"'!B2")} -> 0 | M12: {=INDIRECT("'"&$A12&"'!B3")} -> 0
A13: 10 | B13: {=INDIRECT("'"&$A13&"'!B7")} -> 0 | C13: {=INDIRECT("'"&$A13&"'!B6")} -> 0 | F13: {=INDIRECT("'"&$A13&"'!B8")} -> 0 | G13: {=INDIRECT("'"&$A13&"'!B4")} -> 0 | H13: {=INDIRECT("'"&$A13&"'!B5")} -> 0 | I13: {=INDIRECT("'"&$A13&"'!B1")} -> 0 | J13: {=INDIRECT("'"&$A13&"'!G24")} -> 0 | K13: {=INDIRECT("'"&$A13&"'!B9")} -> 0 | L13: {=INDIRECT("'"&$A13&"'!B2")} -> 0 | M13: {=INDIRECT("'"&$A13&"'!B3")} -> 0
A14: 11 | B14: {=INDIRECT("'"&$A14&"'!B7")} -> 0 | C14: {=INDIRECT("'"&$A14&"'!B6")} -> 0 | F14: {=INDIRECT("'"&$A14&"'!B8")} -> 0 | G14: {=INDIRECT("'"&$A14&"'!B4")} -> 0 | H14: {=INDIRECT("'"&$A14&"'!B5")} -> 0 | I14: {=INDIRECT("'"&$A14&"'!B1")} -> 0 | J14: {=INDIRECT("'"&$A14&"'!G24")} -> 0 | K14: {=INDIRECT("'"&$A14&"'!B9")} -> 0 | L14: {=INDIRECT("'"&$A14&"'!B2")} -> 0 | M14: {=INDIRECT("'"&$A14&"'!B3")} -> 0
A15: 12 | B15: {=INDIRECT("'"&$A15&"'!B7")} -> 0 | C15: {=INDIRECT("'"&$A15&"'!B6")} -> 0 | F15: {=INDIRECT("'"&$A15&"'!B8")} -> 0 | G15: {=INDIRECT("'"&$A15&"'!B4")} -> 0 | H15: {=INDIRECT("'"&$A15&"'!B5")} -> 0 | I15: {=INDIRECT("'"&$A15&"'!B1")} -> 0 | J15: {=INDIRECT("'"&$A15&"'!G24")} -> 0 | K15: {=INDIRECT("'"&$A15&"'!B9")} -> 0 | L15: {=INDIRECT("'"&$A15&"'!B2")} -> 0 | M15: {=INDIRECT("'"&$A15&"'!B3")} -> 0
... A253: 250 | B253: {=INDIRECT("'"&$A253&"'!B7")} -> 0 | C253: {=INDIRECT("'"&$A253&"'!B6")} -> 0 | F253: {=INDIRECT("'"&$A253&"'!B8")} -> 0 | G253: {=INDIRECT("'"&$A253&"'!B4")} -> 0 | H253: {=INDIRECT("'"&$A253&"'!B5")} -> 0 | I253: {=INDIRECT("'"&$A253&"'!B1")} -> 0 | J253: {=INDIRECT("'"&$A253&"'!G24")} -> 0 | K253: {=INDIRECT("'"&$A253&"'!B9")} -> 0 | L253: {=INDIRECT("'"&$A253&"'!B2")} -> 0 | M253: {=INDIRECT("'"&$A253&"'!B3")} -> 0
I254: TOTAL NETO | J254: =SUM(J4:J253) -> 0
I255: IVA | J255: =J254*0.19 -> 0
I256: TOTAL BRUTO | J256: =J254+J255 -> 0

Sheet Items Servicios
A1: ITEMS TABLA DE ADHESIÓN | B1: Monto
A2: Visita de eléctrico (Inspectiva u otros tipos) | B2: 66774.594
A3: Visita Fallida de eléctrico | B3: 33821.691
A4: Metro de tendido cable eléctrico libre de alógeno (desde el punto eléctrico del local al mueble de comunicación) | B4: 27728.929
A5: Zapatilla eléctrica magic y/o normal con caja chuqui | B5: 37924.062
A6: Metro de Instalación tubería PVC | B6: 12851.167
A7: Cableado para la tubería, cable libre de halógeno | B7: 20208.937
A8: Automáticos 16 amperes | B8: 18095.189
A9: Cambio de rieles de módulo Bticino | B9: 15317.634
A10: Enchufes magic macho 16 amperes | B10: 46482.738
A11: Tendido cables de comunicaciones | B11: 42282.465
A12: Cable UTP (conectores RJ 45) | B12: 27498.622
A13: Reposición de cableado interno cobre con roseta modular | B13: 30309.584
... A45: Vacio | B45: 0

Sheet 1
A1: SERVICIO
A2: SOLICITANTE
A3: CATEGORÍA:
A4: ATM:
A5: NOMBRE:
A6: TICKET BCM
A7: OT
A8: TIPO DE MÁQUINA
A9: FECHA EJECUCION
A11: ITEM | B11: Fecha | C11: SERVICIO TARIFADO | D11: CANTIDAD | E11: UNIDAD | F11: VALOR UNITARIO | G11: TOTAL
A12: 1 | F12: =IFERROR(VLOOKUP('1'!C12,'Items Servicios'!A:B,2,0),0) -> 0 | G12: =F12*D12 -> 0
A13: 2 | F13: =IFERROR(VLOOKUP('1'!C13,'Items Servicios'!A:B,2,0),0) -> 0 | G13: =F13*D13 -> 0
A14: 3 | F14: =IFERROR(VLOOKUP('1'!C14,'Items Servicios'!A:B,2,0),0) -> 0 | G14: =F14*D14 -> 0
A15: 4 | F15: =IFERROR(VLOOKUP('1'!C15,'Items Servicios'!A:B,2,0),0) -> 0 | G15: =F15*D15 -> 0
A16: 5 | F16: =IFERROR(VLOOKUP('1'!C16,'Items Servicios'!A:B,2,0),0) -> 0 | G16: =F16*D16 -> 0
A17: 6 | F17: =IFERROR(VLOOKUP('1'!C17,'Items Servicios'!A:B,2,0),0) -> 0 | G17: =F17*D17 -> 0
A18: ITEM | B18: Fecha | C18: SERVICIO NO TARIFADO | D18: CANTIDAD | E18: UNIDAD | F18: VALOR UNITARIO | G18: TOTAL | H18: TARIFAS E ITEMS DEBEN ESTAR AUTORIZADOS POR BANCO
A19: 7 | G19: =F19*D19 -> 0
A20: 8 | G20: =F20*D20 -> 0
A21: 9 | G21: =F21*D21 -> 0
A22: 10 | G22: =F22*D22 -> 0
A23: 11 | G23: =F23*D23 -> 0
D24: VALOR NETO DE SERVICIO | G24: =IFERROR(SUM(G12:G23),0) -> 0
A27: TODO SERVICIO DE CONTINUIDAD OPERATIVA DEBE CONTAR CON TICKET BCM, EL INFORME DEBE ESTAR SUBIDO A BCM
A29: SOPORTE APROBACION / AUTORIZACION

Sheet 2
A1: SERVICIO
A2: SOLICITANTE
A3: CATEGORÍA:
A4: ATM:
A5: NOMBRE:
A6: TICKET BCM
A7: OT
A8: TIPO DE MÁQUINA
A9: FECHA EJECUCION
A11: ITEM | B11: Fecha | C11: SERVICIO TARIFADO | D11: CANTIDAD | E11: UNIDAD | F11: VALOR UNITARIO | G11: TOTAL
A12: 1 | F12: =IFERROR(VLOOKUP('2'!C12,'Items Servicios'!A:B,2,0),0) -> 0 | G12: =F12*D12 -> 0
A13: 2 | F13: =IFERROR(VLOOKUP('2'!C13,'Items Servicios'!A:B,2,0),0) -> 0 | G13: =F13*D13 -> 0
A14: 3 | F14: =IFERROR(VLOOKUP('2'!C14,'Items Servicios'!A:B,2,0),0) -> 0 | G14: =F14*D14 -> 0
A15: 4 | F15: =IFERROR(VLOOKUP('2'!C15,'Items Servicios'!A:B,2,0),0) -> 0 | G15: =F15*D15 -> 0
A16: 5 | F16: =IFERROR(VLOOKUP('2'!C16,'Items Servicios'!A:B,2,0),0) -> 0 | G16: =F16*D16 -> 0
A17: 6 | F17: =IFERROR(VLOOKUP('2'!C17,'Items Servicios'!A:B,2,0),0) -> 0 | G17: =F17*D17 -> 0
A18: ITEM | B18: Fecha | C18: SERVICIO NO TARIFADO | D18: CANTIDAD | E18: UNIDAD | F18: VALOR UNITARIO | G18: TOTAL | H18: TARIFAS E ITEMS DEBEN ESTAR AUTORIZADOS POR BANCO
A19: 7 | G19: =F19*D19 -> 0
A20: 8 | G20: =F20*D20 -> 0
A21: 9 | G21: =F21*D21 -> 0
A22: 10 | G22: =F22*D22 -> 0
A23: 11 | G23: =F23*D23 -> 0
D24: VALOR NETO DE SERVICIO | G24: =IFERROR(SUM(G12:G23),0) -> 0
A27: TODO SERVICIO DE CONTINUIDAD OPERATIVA DEBE CONTAR CON TICKET BCM, EL INFORME DEBE ESTAR SUBIDO A BCM
A29: SOPORTE APROBACION / AUTORIZACION

Sheet 3
A1: SERVICIO
A2: SOLICITANTE
A3: CATEGORÍA:
A4: ATM:
A5: NOMBRE:
A6: TICKET BCM
A7: OT
A8: TIPO DE MÁQUINA
A9: FECHA EJECUCION
A11: ITEM | B11: Fecha | C11: SERVICIO TARIFADO | D11: CANTIDAD | E11: UNIDAD | F11: VALOR UNITARIO | G11: TOTAL
A12: 1 | F12: =IFERROR(VLOOKUP('3'!C12,'Items Servicios'!A:B,2,0),0) -> 0 | G12: =F12*D12 -> 0
A13: 2 | F13: =IFERROR(VLOOKUP('3'!C13,'Items Servicios'!A:B,2,0),0) -> 0 | G13: =F13*D13 -> 0
A14: 3 | F14: =IFERROR(VLOOKUP('3'!C14,'Items Servicios'!A:B,2,0),0) -> 0 | G14: =F14*D14 -> 0
A15: 4 | F15: =IFERROR(VLOOKUP('3'!C15,'Items Servicios'!A:B,2,0),0) -> 0 | G15: =F15*D15 -> 0
A16: 5 | F16: =IFERROR(VLOOKUP('3'!C16,'Items Servicios'!A:B,2,0),0) -> 0 | G16: =F16*D16 -> 0
A17: 6 | F17: =IFERROR(VLOOKUP('3'!C17,'Items Servicios'!A:B,2,0),0) -> 0 | G17: =F17*D17 -> 0
A18: ITEM | B18: Fecha | C18: SERVICIO NO TARIFADO | D18: CANTIDAD | E18: UNIDAD | F18: VALOR UNITARIO | G18: TOTAL | H18: TARIFAS E ITEMS DEBEN ESTAR AUTORIZADOS POR BANCO
A19: 7 | G19: =F19*D19 -> 0
A20: 8 | G20: =F20*D20 -> 0
A21: 9 | G21: =F21*D21 -> 0
A22: 10 | G22: =F22*D22 -> 0
A23: 11 | G23: =F23*D23 -> 0
D24: VALOR NETO DE SERVICIO | G24: =IFERROR(SUM(G12:G23),0) -> 0
A27: TODO SERVICIO DE CONTINUIDAD OPERATIVA DEBE CONTAR CON TICKET BCM, EL INFORME DEBE ESTAR SUBIDO A BCM
A29: SOPORTE APROBACION / AUTORIZACION

Sheet 4
A1: SERVICIO
A2: SOLICITANTE
A3: CATEGORÍA:
A4: ATM:
A5: NOMBRE:
A6: TICKET BCM
A7: OT
A8: TIPO DE MÁQUINA
A9: FECHA EJECUCION
A11: ITEM | B11: Fecha | C11: SERVICIO TARIFADO | D11: CANTIDAD | E11: UNIDAD | F11: VALOR UNITARIO | G11: TOTAL
A12: 1 | F12: =IFERROR(VLOOKUP('4'!C12,'Items Servicios'!A:B,2,0),0) -> 0 | G12: =F12*D12 -> 0
A13: 2 | F13: =IFERROR(VLOOKUP('4'!C13,'Items Servicios'!A:B,2,0),0) -> 0 | G13: =F13*D13 -> 0
A14: 3 | F14: =IFERROR(VLOOKUP('4'!C14,'Items Servicios'!A:B,2,0),0) -> 0 | G14: =F14*D14 -> 0
A15: 4 | F15: =IFERROR(VLOOKUP('4'!C15,'Items Servicios'!A:B,2,0),0) -> 0 | G15: =F15*D15 -> 0
A16: 5 | F16: =IFERROR(VLOOKUP('4'!C16,'Items Servicios'!A:B,2,0),0) -> 0 | G16: =F16*D16 -> 0
A17: 6 | F17: =IFERROR(VLOOKUP('4'!C17,'Items Servicios'!A:B,2,0),0) -> 0 | G17: =F17*D17 -> 0
A18: ITEM | B18: Fecha | C18: SERVICIO NO TARIFADO | D18: CANTIDAD | E18: UNIDAD | F18: VALOR UNITARIO | G18: TOTAL | H18: TARIFAS E ITEMS DEBEN ESTAR AUTORIZADOS POR BANCO
A19: 7 | G19: =F19*D19 -> 0
A20: 8 | G20: =F20*D20 -> 0
A21: 9 | G21: =F21*D21 -> 0
A22: 10 | G22: =F22*D22 -> 0
A23: 11 | G23: =F23*D23 -> 0
D24: VALOR NETO DE SERVICIO | G24: =IFERROR(SUM(G12:G23),0) -> 0
A27: TODO SERVICIO DE CONTINUIDAD OPERATIVA DEBE CONTAR CON TICKET BCM, EL INFORME DEBE ESTAR SUBIDO A BCM
A29: SOPORTE APROBACION / AUTORIZACION

Sheet 5
A1: SERVICIO
A2: SOLICITANTE
A3: CATEGORÍA:
A4: ATM:
A5: NOMBRE:
A6: TICKET BCM
A7: OT
A8: TIPO DE MÁQUINA
A9: FECHA EJECUCION
A11: ITEM | B11: Fecha | C11: SERVICIO TARIFADO | D11: CANTIDAD | E11: UNIDAD | F11: VALOR UNITARIO | G11: TOTAL
A12: 1 | F12: =IFERROR(VLOOKUP('5'!C12,'Items Servicios'!A:B,2,0),0) -> 0 | G12: =F12*D12 -> 0
A13: 2 | F13: =IFERROR(VLOOKUP('5'!C13,'Items Servicios'!A:B,2,0),0) -> 0 | G13: =F13*D13 -> 0
A14: 3 | F14: =IFERROR(VLOOKUP('5'!C14,'Items Servicios'!A:B,2,0),0) -> 0 | G14: =F14*D14 -> 0
A15: 4 | F15: =IFERROR(VLOOKUP('5'!C15,'Items Servicios'!A:B,2,0),0) -> 0 | G15: =F15*D15 -> 0
A16: 5 | F16: =IFERROR(VLOOKUP('5'!C16,'Items Servicios'!A:B,2,0),0) -> 0 | G16: =F16*D16 -> 0
A17: 6 | F17: =IFERROR(VLOOKUP('5'!C17,'Items Servicios'!A:B,2,0),0) -> 0 | G17: =F17*D17 -> 0
A18: ITEM | B18: Fecha | C18: SERVICIO NO TARIFADO | D18: CANTIDAD | E18: UNIDAD | F18: VALOR UNITARIO | G18: TOTAL | H18: TARIFAS E ITEMS DEBEN ESTAR AUTORIZADOS POR BANCO
A19: 7 | G19: =F19*D19 -> 0
A20: 8 | G20: =F20*D20 -> 0
A21: 9 | G21: =F21*D21 -> 0
A22: 10 | G22: =F22*D22 -> 0
A23: 11 | G23: =F23*D23 -> 0
D24: VALOR NETO DE SERVICIO | G24: =IFERROR(SUM(G12:G23),0) -> 0
A27: TODO SERVICIO DE CONTINUIDAD OPERATIVA DEBE CONTAR CON TICKET BCM, EL INFORME DEBE ESTAR SUBIDO A BCM
A29: SOPORTE APROBACION / AUTORIZACION

Sheet 6
A1: SERVICIO
A2: SOLICITANTE
A3: CATEGORÍA:
A4: ATM:
A5: NOMBRE:
A6: TICKET BCM
A7: OT
A8: TIPO DE MÁQUINA
A9: FECHA EJECUCION
A11: ITEM | B11: Fecha | C11: SERVICIO TARIFADO | D11: CANTIDAD | E11: UNIDAD | F11: VALOR UNITARIO | G11: TOTAL
A12: 1 | F12: =IFERROR(VLOOKUP('6'!C12,'Items Servicios'!A:B,2,0),0) -> 0 | G12: =F12*D12 -> 0
A13: 2 | F13: =IFERROR(VLOOKUP('6'!C13,'Items Servicios'!A:B,2,0),0) -> 0 | G13: =F13*D13 -> 0
A14: 3 | F14: =IFERROR(VLOOKUP('6'!C14,'Items Servicios'!A:B,2,0),0) -> 0 | G14: =F14*D14 -> 0
A15: 4 | F15: =IFERROR(VLOOKUP('6'!C15,'Items Servicios'!A:B,2,0),0) -> 0 | G15: =F15*D15 -> 0
A16: 5 | F16: =IFERROR(VLOOKUP('6'!C16,'Items Servicios'!A:B,2,0),0) -> 0 | G16: =F16*D16 -> 0
A17: 6 | F17: =IFERROR(VLOOKUP('6'!C17,'Items Servicios'!A:B,2,0),0) -> 0 | G17: =F17*D17 -> 0
A18: ITEM | B18: Fecha | C18: SERVICIO NO TARIFADO | D18: CANTIDAD | E18: UNIDAD | F18: VALOR UNITARIO | G18: TOTAL | H18: TARIFAS E ITEMS DEBEN ESTAR AUTORIZADOS POR BANCO
A19: 7 | G19: =F19*D19 -> 0
A20: 8 | G20: =F20*D20 -> 0
A21: 9 | G21: =F21*D21 -> 0
A22: 10 | G22: =F22*D22 -> 0
A23: 11 | G23: =F23*D23 -> 0
D24: VALOR NETO DE SERVICIO | G24: =IFERROR(SUM(G12:G23),0) -> 0
A27: TODO SERVICIO DE CONTINUIDAD OPERATIVA DEBE CONTAR CON TICKET BCM, EL INFORME DEBE ESTAR SUBIDO A BCM
A29: SOPORTE APROBACION / AUTORIZACION

Sheet 7
A1: SERVICIO
A2: SOLICITANTE
A3: CATEGORÍA:
A4: ATM:
A5: NOMBRE:
A6: TICKET BCM
A7: OT
A8: TIPO DE MÁQUINA
A9: FECHA EJECUCION
A11: ITEM | B11: Fecha | C11: SERVICIO TARIFADO | D11: CANTIDAD | E11: UNIDAD | F11: VALOR UNITARIO | G11: TOTAL
A12: 1 | F12: =IFERROR(VLOOKUP('7'!C12,'Items Servicios'!A:B,2,0),0) -> 0 | G12: =F12*D12 -> 0
A13: 2 | F13: =IFERROR(VLOOKUP('7'!C13,'Items Servicios'!A:B,2,0),0) -> 0 | G13: =F13*D13 -> 0
A14: 3 | F14: =IFERROR(VLOOKUP('7'!C14,'Items Servicios'!A:B,2,0),0) -> 0 | G14: =F14*D14 -> 0
A15: 4 | F15: =IFERROR(VLOOKUP('7'!C15,'Items Servicios'!A:B,2,0),0) -> 0 | G15: =F15*D15 -> 0
A16: 5 | F16: =IFERROR(VLOOKUP('7'!C16,'Items Servicios'!A:B,2,0),0) -> 0 | G16: =F16*D16 -> 0
A17: 6 | F17: =IFERROR(VLOOKUP('7'!C17,'Items Servicios'!A:B,2,0),0) -> 0 | G17: =F17*D17 -> 0
A18: ITEM | B18: Fecha | C18: SERVICIO NO TARIFADO | D18: CANTIDAD | E18: UNIDAD | F18: VALOR UNITARIO | G18: TOTAL | H18: TARIFAS E ITEMS DEBEN ESTAR AUTORIZADOS POR BANCO
A19: 7 | G19: =F19*D19 -> 0
A20: 8 | G20: =F20*D20 -> 0
A21: 9 | G21: =F21*D21 -> 0
A22: 10 | G22: =F22*D22 -> 0
A23: 11 | G23: =F23*D23 -> 0
D24: VALOR NETO DE SERVICIO | G24: =IFERROR(SUM(G12:G23),0) -> 0
A27: TODO SERVICIO DE CONTINUIDAD OPERATIVA DEBE CONTAR CON TICKET BCM, EL INFORME DEBE ESTAR SUBIDO A BCM
A29: SOPORTE APROBACION / AUTORIZACION

Sheet 8
A1: SERVICIO
A2: SOLICITANTE
A3: CATEGORÍA:
A4: ATM:
A5: NOMBRE:
A6: TICKET BCM
A7: OT
A8: TIPO DE MÁQUINA
A9: FECHA EJECUCION
A11: ITEM | B11: Fecha | C11: SERVICIO TARIFADO | D11: CANTIDAD | E11: UNIDAD | F11: VALOR UNITARIO | G11: TOTAL
A12: 1 | F12: =IFERROR(VLOOKUP('8'!C12,'Items Servicios'!A:B,2,0),0) -> 0 | G12: =F12*D12 -> 0
A13: 2 | F13: =IFERROR(VLOOKUP('8'!C13,'Items Servicios'!A:B,2,0),0) -> 0 | G13: =F13*D13 -> 0
A14: 3 | F14: =IFERROR(VLOOKUP('8'!C14,'Items Servicios'!A:B,2,0),0) -> 0 | G14: =F14*D14 -> 0
A15: 4 | F15: =IFERROR(VLOOKUP('8'!C15,'Items Servicios'!A:B,2,0),0) -> 0 | G15: =F15*D15 -> 0
A16: 5 | F16: =IFERROR(VLOOKUP('8'!C16,'Items Servicios'!A:B,2,0),0) -> 0 | G16: =F16*D16 -> 0
A17: 6 | F17: =IFERROR(VLOOKUP('8'!C17,'Items Servicios'!A:B,2,0),0) -> 0 | G17: =F17*D17 -> 0
A18: ITEM | B18: Fecha | C18: SERVICIO NO TARIFADO | D18: CANTIDAD | E18: UNIDAD | F18: VALOR UNITARIO | G18: TOTAL | H18: TARIFAS E ITEMS DEBEN ESTAR AUTORIZADOS POR BANCO
A19: 7 | G19: =F19*D19 -> 0
A20: 8 | G20: =F20*D20 -> 0
A21: 9 | G21: =F21*D21 -> 0
A22: 10 | G22: =F22*D22 -> 0
A23: 11 | G23: =F23*D23 -> 0
D24: VALOR NETO DE SERVICIO | G24: =IFERROR(SUM(G12:G23),0) -> 0
A27: TODO SERVICIO DE CONTINUIDAD OPERATIVA DEBE CONTAR CON TICKET BCM, EL INFORME DEBE ESTAR SUBIDO A BCM
A29: SOPORTE APROBACION / AUTORIZACION

Sheet 9
A1: SERVICIO
A2: SOLICITANTE
A3: CATEGORÍA:
A4: ATM:
A5: NOMBRE:
A6: TICKET BCM
A7: OT
A8: TIPO DE MÁQUINA
A9: FECHA EJECUCION
A11: ITEM | B11: Fecha | C11: SERVICIO TARIFADO | D11: CANTIDAD | E11: UNIDAD | F11: VALOR UNITARIO | G11: TOTAL
A12: 1 | F12: =IFERROR(VLOOKUP('9'!C12,'Items Servicios'!A:B,2,0),0) -> 0 | G12: =F12*D12 -> 0
A13: 2 | F13: =IFERROR(VLOOKUP('9'!C13,'Items Servicios'!A:B,2,0),0) -> 0 | G13: =F13*D13 -> 0
A14: 3 | F14: =IFERROR(VLOOKUP('9'!C14,'Items Servicios'!A:B,2,0),0) -> 0 | G14: =F14*D14 -> 0
A15: 4 | F15: =IFERROR(VLOOKUP('9'!C15,'Items Servicios'!A:B,2,0),0) -> 0 | G15: =F15*D15 -> 0
A16: 5 | F16: =IFERROR(VLOOKUP('9'!C16,'Items Servicios'!A:B,2,0),0) -> 0 | G16: =F16*D16 -> 0
A17: 6 | F17: =IFERROR(VLOOKUP('9'!C17,'Items Servicios'!A:B,2,0),0) -> 0 | G17: =F17*D17 -> 0
A18: ITEM | B18: Fecha | C18: SERVICIO NO TARIFADO | D18: CANTIDAD | E18: UNIDAD | F18: VALOR UNITARIO | G18: TOTAL | H18: TARIFAS E ITEMS DEBEN ESTAR AUTORIZADOS POR BANCO
A19: 7 | G19: =F19*D19 -> 0
A20: 8 | G20: =F20*D20 -> 0
A21: 9 | G21: =F21*D21 -> 0
A22: 10 | G22: =F22*D22 -> 0
A23: 11 | G23: =F23*D23 -> 0
D24: VALOR NETO DE SERVICIO | G24: =IFERROR(SUM(G12:G23),0) -> 0
A27: TODO SERVICIO DE CONTINUIDAD OPERATIVA DEBE CONTAR CON TICKET BCM, EL INFORME DEBE ESTAR SUBIDO A BCM
A29: SOPORTE APROBACION / AUTORIZACION

Sheet 10
A1: SERVICIO
A2: SOLICITANTE
A3: CATEGORÍA:
A4: ATM:
A5: NOMBRE:
A6: TICKET BCM
A7: OT
A8: TIPO DE MÁQUINA
A9: FECHA EJECUCION
A11: ITEM | B11: Fecha | C11: SERVICIO TARIFADO | D11: CANTIDAD | E11: UNIDAD | F11: VALOR UNITARIO | G11: TOTAL
A12: 1 | F12: =IFERROR(VLOOKUP('10'!C12,'Items Servicios'!A:B,2,0),0) -> 0 | G12: =F12*D12 -> 0
A13: 2 | F13: =IFERROR(VLOOKUP('10'!C13,'Items Servicios'!A:B,2,0),0) -> 0 | G13: =F13*D13 -> 0
A14: 3 | F14: =IFERROR(VLOOKUP('10'!C14,'Items Servicios'!A:B,2,0),0) -> 0 | G14: =F14*D14 -> 0
A15: 4 | F15: =IFERROR(VLOOKUP('10'!C15,'Items Servicios'!A:B,2,0),0) -> 0 | G15: =F15*D15 -> 0
A16: 5 | F16: =IFERROR(VLOOKUP('10'!C16,'Items Servicios'!A:B,2,0),0) -> 0 | G16: =F16*D16 -> 0
A17: 6 | F17: =IFERROR(VLOOKUP('10'!C17,'Items Servicios'!A:B,2,0),0) -> 0 | G17: =F17*D17 -> 0
A18: ITEM | B18: Fecha | C18: SERVICIO NO TARIFADO | D18: CANTIDAD | E18: UNIDAD | F18: VALOR UNITARIO | G18: TOTAL | H18: TARIFAS E ITEMS DEBEN ESTAR AUTORIZADOS POR BANCO
A19: 7 | G19: =F19*D19 -> 0
A20: 8 | G20: =F20*D20 -> 0
A21: 9 | G21: =F21*D21 -> 0
A22: 10 | G22: =F22*D22 -> 0
A23: 11 | G23: =F23*D23 -> 0
D24: VALOR NETO DE SERVICIO | G24: =IFERROR(SUM(G12:G23),0) -> 0
A27: TODO SERVICIO DE CONTINUIDAD OPERATIVA DEBE CONTAR CON TICKET BCM, EL INFORME DEBE ESTAR SUBIDO A BCM
A29: SOPORTE APROBACION / AUTORIZACION

Sheet 11
A1: SERVICIO
A2: SOLICITANTE
A3: CATEGORÍA:
A4: ATM:
A5: NOMBRE:
A6: TICKET BCM
A7: OT
A8: TIPO DE MÁQUINA
A9: FECHA EJECUCION
A11: ITEM | B11: Fecha | C11: SERVICIO TARIFADO | D11: CANTIDAD | E11: UNIDAD | F11: VALOR UNITARIO | G11: TOTAL
A12: 1 | F12: =IFERROR(VLOOKUP('11'!C12,'Items Servicios'!A:B,2,0),0) -> 0 | G12: =F12*D12 -> 0
A13: 2 | F13: =IFERROR(VLOOKUP('11'!C13,'Items Servicios'!A:B,2,0),0) -> 0 | G13: =F13*D13 -> 0
A14: 3 | F14: =IFERROR(VLOOKUP('11'!C14,'Items Servicios'!A:B,2,0),0) -> 0 | G14: =F14*D14 -> 0
A15: 4 | F15: =IFERROR(VLOOKUP('11'!C15,'Items Servicios'!A:B,2,0),0) -> 0 | G15: =F15*D15 -> 0
A16: 5 | F16: =IFERROR(VLOOKUP('11'!C16,'Items Servicios'!A:B,2,0),0) -> 0 | G16: =F16*D16 -> 0
A17: 6 | F17: =IFERROR(VLOOKUP('11'!C17,'Items Servicios'!A:B,2,0),0) -> 0 | G17: =F17*D17 -> 0
A18: ITEM | B18: Fecha | C18: SERVICIO NO TARIFADO | D18: CANTIDAD | E18: UNIDAD | F18: VALOR UNITARIO | G18: TOTAL | H18: TARIFAS E ITEMS DEBEN ESTAR AUTORIZADOS POR BANCO
A19: 7 | G19: =F19*D19 -> 0
A20: 8 | G20: =F20*D20 -> 0
A21: 9 | G21: =F21*D21 -> 0
A22: 10 | G22: =F22*D22 -> 0
A23: 11 | G23: =F23*D23 -> 0
D24: VALOR NETO DE SERVICIO | G24: =IFERROR(SUM(G12:G23),0) -> 0
A27: TODO SERVICIO DE CONTINUIDAD OPERATIVA DEBE CONTAR CON TICKET BCM, EL INFORME DEBE ESTAR SUBIDO A BCM
A29: SOPORTE APROBACION / AUTORIZACION

Sheet 12
A1: SERVICIO
A2: SOLICITANTE
A3: CATEGORÍA:
A4: ATM:
A5: NOMBRE:
A6: TICKET BCM
A7: OT
A8: TIPO DE MÁQUINA
A9: FECHA EJECUCION
A11: ITEM | B11: Fecha | C11: SERVICIO TARIFADO | D11: CANTIDAD | E11: UNIDAD | F11: VALOR UNITARIO | G11: TOTAL
A12: 1 | F12: =IFERROR(VLOOKUP('12'!C12,'Items Servicios'!A:B,2,0),0) -> 0 | G12: =F12*D12 -> 0
A13: 2 | F13: =IFERROR(VLOOKUP('12'!C13,'Items Servicios'!A:B,2,0),0) -> 0 | G13: =F13*D13 -> 0
A14: 3 | F14: =IFERROR(VLOOKUP('12'!C14,'Items Servicios'!A:B,2,0),0) -> 0 | G14: =F14*D14 -> 0
A15: 4 | F15: =IFERROR(VLOOKUP('12'!C15,'Items Servicios'!A:B,2,0),0) -> 0 | G15: =F15*D15 -> 0
A16: 5 | F16: =IFERROR(VLOOKUP('12'!C16,'Items Servicios'!A:B,2,0),0) -> 0 | G16: =F16*D16 -> 0
A17: 6 | F17: =IFERROR(VLOOKUP('12'!C17,'Items Servicios'!A:B,2,0),0) -> 0 | G17: =F17*D17 -> 0
A18: ITEM | B18: Fecha | C18: SERVICIO NO TARIFADO | D18: CANTIDAD | E18: UNIDAD | F18: VALOR UNITARIO | G18: TOTAL | H18: TARIFAS E ITEMS DEBEN ESTAR AUTORIZADOS POR BANCO
A19: 7 | G19: =F19*D19 -> 0
A20: 8 | G20: =F20*D20 -> 0
A21: 9 | G21: =F21*D21 -> 0
A22: 10 | G22: =F22*D22 -> 0
A23: 11 | G23: =F23*D23 -> 0
D24: VALOR NETO DE SERVICIO | G24: =IFERROR(SUM(G12:G23),0) -> 0
A27: TODO SERVICIO DE CONTINUIDAD OPERATIVA DEBE CONTAR CON TICKET BCM, EL INFORME DEBE ESTAR SUBIDO A BCM
A29: SOPORTE APROBACION / AUTORIZACION

Sheet 13
A1: SERVICIO
A2: SOLICITANTE
A3: CATEGORÍA:
A4: ATM:
A5: NOMBRE:
A6: TICKET BCM
A7: OT
A8: TIPO DE MÁQUINA
A9: FECHA EJECUCION
A11: ITEM | B11: Fecha | C11: SERVICIO TARIFADO | D11: CANTIDAD | E11: UNIDAD | F11: VALOR UNITARIO | G11: TOTAL
A12: 1 | F12: =IFERROR(VLOOKUP('13'!C12,'Items Servicios'!A:B,2,0),0) -> 0 | G12: =F12*D12 -> 0
A13: 2 | F13: =IFERROR(VLOOKUP('13'!C13,'Items Servicios'!A:B,2,0),0) -> 0 | G13: =F13*D13 -> 0
A14: 3 | F14: =IFERROR(VLOOKUP('13'!C14,'Items Servicios'!A:B,2,0),0) -> 0 | G14: =F14*D14 -> 0
A15: 4 | F15: =IFERROR(VLOOKUP('13'!C15,'Items Servicios'!A:B,2,0),0) -> 0 | G15: =F15*D15 -> 0
A16: 5 | F16: =IFERROR(VLOOKUP('13'!C16,'Items Servicios'!A:B,2,0),0) -> 0 | G16: =F16*D16 -> 0
A17: 6 | F17: =IFERROR(VLOOKUP('13'!C17,'Items Servicios'!A:B,2,0),0) -> 0 | G17: =F17*D17 -> 0
A18: ITEM | B18: Fecha | C18: SERVICIO NO TARIFADO | D18: CANTIDAD | E18: UNIDAD | F18: VALOR UNITARIO | G18: TOTAL | H18: TARIFAS E ITEMS DEBEN ESTAR AUTORIZADOS POR BANCO
A19: 7 | G19: =F19*D19 -> 0
A20: 8 | G20: =F20*D20 -> 0
A21: 9 | G21: =F21*D21 -> 0
A22: 10 | G22: =F22*D22 -> 0
A23: 11 | G23: =F23*D23 -> 0
D24: VALOR NETO DE SERVICIO | G24: =IFERROR(SUM(G12:G23),0) -> 0
A27: TODO SERVICIO DE CONTINUIDAD OPERATIVA DEBE CONTAR CON TICKET BCM, EL INFORME DEBE ESTAR SUBIDO A BCM
A29: SOPORTE APROBACION / AUTORIZACION

Sheet 14
A1: SERVICIO
A2: SOLICITANTE
A3: CATEGORÍA:
A4: ATM:
A5: NOMBRE:
A6: TICKET BCM
A7: OT
A8: TIPO DE MÁQUINA
A9: FECHA EJECUCION
A11: ITEM | B11: Fecha | C11: SERVICIO TARIFADO | D11: CANTIDAD | E11: UNIDAD | F11: VALOR UNITARIO | G11: TOTAL
A12: 1 | F12: =IFERROR(VLOOKUP('14'!C12,'Items Servicios'!A:B,2,0),0) -> 0 | G12: =F12*D12 -> 0
A13: 2 | F13: =IFERROR(VLOOKUP('14'!C13,'Items Servicios'!A:B,2,0),0) -> 0 | G13: =F13*D13 -> 0
A14: 3 | F14: =IFERROR(VLOOKUP('14'!C14,'Items Servicios'!A:B,2,0),0) -> 0 | G14: =F14*D14 -> 0
A15: 4 | F15: =IFERROR(VLOOKUP('14'!C15,'Items Servicios'!A:B,2,0),0) -> 0 | G15: =F15*D15 -> 0
A16: 5 | F16: =IFERROR(VLOOKUP('14'!C16,'Items Servicios'!A:B,2,0),0) -> 0 | G16: =F16*D16 -> 0
A17: 6 | F17: =IFERROR(VLOOKUP('14'!C17,'Items Servicios'!A:B,2,0),0) -> 0 | G17: =F17*D17 -> 0
A18: ITEM | B18: Fecha | C18: SERVICIO NO TARIFADO | D18: CANTIDAD | E18: UNIDAD | F18: VALOR UNITARIO | G18: TOTAL | H18: TARIFAS E ITEMS DEBEN ESTAR AUTORIZADOS POR BANCO
A19: 7 | G19: =F19*D19 -> 0
A20: 8 | G20: =F20*D20 -> 0
A21: 9 | G21: =F21*D21 -> 0
A22: 10 | G22: =F22*D22 -> 0
A23: 11 | G23: =F23*D23 -> 0
D24: VALOR NETO DE SERVICIO | G24: =IFERROR(SUM(G12:G23),0) -> 0
A27: TODO SERVICIO DE CONTINUIDAD OPERATIVA DEBE CONTAR CON TICKET BCM, EL INFORME DEBE ESTAR SUBIDO A BCM
A29: SOPORTE APROBACION / AUTORIZACION

Sheet 15
A1: SERVICIO
A2: SOLICITANTE
A3: CATEGORÍA:
A4: ATM:
A5: NOMBRE:
A6: TICKET BCM
A7: OT
A8: TIPO DE MÁQUINA
A9: FECHA EJECUCION
A11: ITEM | B11: Fecha | C11: SERVICIO TARIFADO | D11: CANTIDAD | E11: UNIDAD | F11: VALOR UNITARIO | G11: TOTAL
A12: 1 | F12: =IFERROR(VLOOKUP('15'!C12,'Items Servicios'!A:B,2,0),0) -> 0 | G12: =F12*D12 -> 0
A13: 2 | F13: =IFERROR(VLOOKUP('15'!C13,'Items Servicios'!A:B,2,0),0) -> 0 | G13: =F13*D13 -> 0
A14: 3 | F14: =IFERROR(VLOOKUP('15'!C14,'Items Servicios'!A:B,2,0),0) -> 0 | G14: =F14*D14 -> 0
A15: 4 | F15: =IFERROR(VLOOKUP('15'!C15,'Items Servicios'!A:B,2,0),0) -> 0 | G15: =F15*D15 -> 0
A16: 5 | F16: =IFERROR(VLOOKUP('15'!C16,'Items Servicios'!A:B,2,0),0) -> 0 | G16: =F16*D16 -> 0
A17: 6 | F17: =IFERROR(VLOOKUP('15'!C17,'Items Servicios'!A:B,2,0),0) -> 0 | G17: =F17*D17 -> 0
A18: ITEM | B18: Fecha | C18: SERVICIO NO TARIFADO | D18: CANTIDAD | E18: UNIDAD | F18: VALOR UNITARIO | G18: TOTAL | H18: TARIFAS E ITEMS DEBEN ESTAR AUTORIZADOS POR BANCO
A19: 7 | G19: =F19*D19 -> 0
A20: 8 | G20: =F20*D20 -> 0
A21: 9 | G21: =F21*D21 -> 0
A22: 10 | G22: =F22*D22 -> 0
A23: 11 | G23: =F23*D23 -> 0
D24: VALOR NETO DE SERVICIO | G24: =IFERROR(SUM(G12:G23),0) -> 0
A27: TODO SERVICIO DE CONTINUIDAD OPERATIVA DEBE CONTAR CON TICKET BCM, EL INFORME DEBE ESTAR SUBIDO A BCM
A29: SOPORTE APROBACION / AUTORIZACION

Sheet 16
A1: SERVICIO
A2: SOLICITANTE
A3: CATEGORÍA:
A4: ATM:
A5: NOMBRE:
A6: TICKET BCM
A7: OT
A8: TIPO DE MÁQUINA
A9: FECHA EJECUCION
A11: ITEM | B11: Fecha | C11: SERVICIO TARIFADO | D11: CANTIDAD | E11: UNIDAD | F11: VALOR UNITARIO | G11: TOTAL
A12: 1 | F12: =IFERROR(VLOOKUP('16'!C12,'Items Servicios'!A:B,2,0),0) -> 0 | G12: =F12*D12 -> 0
A13: 2 | F13: =IFERROR(VLOOKUP('16'!C13,'Items Servicios'!A:B,2,0),0) -> 0 | G13: =F13*D13 -> 0
A14: 3 | F14: =IFERROR(VLOOKUP('16'!C14,'Items Servicios'!A:B,2,0),0) -> 0 | G14: =F14*D14 -> 0
A15: 4 | F15: =IFERROR(VLOOKUP('16'!C15,'Items Servicios'!A:B,2,0),0) -> 0 | G15: =F15*D15 -> 0
A16: 5 | F16: =IFERROR(VLOOKUP('16'!C16,'Items Servicios'!A:B,2,0),0) -> 0 | G16: =F16*D16 -> 0
A17: 6 | F17: =IFERROR(VLOOKUP('16'!C17,'Items Servicios'!A:B,2,0),0) -> 0 | G17: =F17*D17 -> 0
A18: ITEM | B18: Fecha | C18: SERVICIO NO TARIFADO | D18: CANTIDAD | E18: UNIDAD | F18: VALOR UNITARIO | G18: TOTAL | H18: TARIFAS E ITEMS DEBEN ESTAR AUTORIZADOS POR BANCO
A19: 7 | G19: =F19*D19 -> 0
A20: 8 | G20: =F20*D20 -> 0
A21: 9 | G21: =F21*D21 -> 0
A22: 10 | G22: =F22*D22 -> 0
A23: 11 | G23: =F23*D23 -> 0
D24: VALOR NETO DE SERVICIO | G24: =IFERROR(SUM(G12:G23),0) -> 0
A27: TODO SERVICIO DE CONTINUIDAD OPERATIVA DEBE CONTAR CON TICKET BCM, EL INFORME DEBE ESTAR SUBIDO A BCM
A29: SOPORTE APROBACION / AUTORIZACION

Sheet 17
A1: SERVICIO
A2: SOLICITANTE
A3: CATEGORÍA:
A4: ATM:
A5: NOMBRE:
A6: TICKET BCM
A7: OT
A8: TIPO DE MÁQUINA
A9: FECHA EJECUCION
A11: ITEM | B11: Fecha | C11: SERVICIO TARIFADO | D11: CANTIDAD | E11: UNIDAD | F11: VALOR UNITARIO | G11: TOTAL
A12: 1 | F12: =IFERROR(VLOOKUP('17'!C12,'Items Servicios'!A:B,2,0),0) -> 0 | G12: =F12*D12 -> 0
A13: 2 | F13: =IFERROR(VLOOKUP('17'!C13,'Items Servicios'!A:B,2,0),0) -> 0 | G13: =F13*D13 -> 0
A14: 3 | F14: =IFERROR(VLOOKUP('17'!C14,'Items Servicios'!A:B,2,0),0) -> 0 | G14: =F14*D14 -> 0
A15: 4 | F15: =IFERROR(VLOOKUP('17'!C15,'Items Servicios'!A:B,2,0),0) -> 0 | G15: =F15*D15 -> 0
A16: 5 | F16: =IFERROR(VLOOKUP('17'!C16,'Items Servicios'!A:B,2,0),0) -> 0 | G16: =F16*D16 -> 0
A17: 6 | F17: =IFERROR(VLOOKUP('17'!C17,'Items Servicios'!A:B,2,0),0) -> 0 | G17: =F17*D17 -> 0
A18: ITEM | B18: Fecha | C18: SERVICIO NO TARIFADO | D18: CANTIDAD | E18: UNIDAD | F18: VALOR UNITARIO | G18: TOTAL | H18: TARIFAS E ITEMS DEBEN ESTAR AUTORIZADOS POR BANCO
A19: 7 | G19: =F19*D19 -> 0
A20: 8 | G20: =F20*D20 -> 0
A21: 9 | G21: =F21*D21 -> 0
A22: 10 | G22: =F22*D22 -> 0
A23: 11 | G23: =F23*D23 -> 0
D24: VALOR NETO DE SERVICIO | G24: =IFERROR(SUM(G12:G23),0) -> 0
A27: TODO SERVICIO DE CONTINUIDAD OPERATIVA DEBE CONTAR CON TICKET BCM, EL INFORME DEBE ESTAR SUBIDO A BCM
A29: SOPORTE APROBACION / AUTORIZACION

Sheet 18
A1: SERVICIO
A2: SOLICITANTE
A3: CATEGORÍA:
A4: ATM:
A5: NOMBRE:
A6: TICKET BCM
A7: OT
A8: TIPO DE MÁQUINA
A9: FECHA EJECUCION
A11: ITEM | B11: Fecha | C11: SERVICIO TARIFADO | D11: CANTIDAD | E11: UNIDAD | F11: VALOR UNITARIO | G11: TOTAL
A12: 1 | F12: =IFERROR(VLOOKUP('18'!C12,'Items Servicios'!A:B,2,0),0) -> 0 | G12: =F12*D12 -> 0
A13: 2 | F13: =IFERROR(VLOOKUP('18'!C13,'Items Servicios'!A:B,2,0),0) -> 0 | G13: =F13*D13 -> 0
A14: 3 | F14: =IFERROR(VLOOKUP('18'!C14,'Items Servicios'!A:B,2,0),0) -> 0 | G14: =F14*D14 -> 0
A15: 4 | F15: =IFERROR(VLOOKUP('18'!C15,'Items Servicios'!A:B,2,0),0) -> 0 | G15: =F15*D15 -> 0
A16: 5 | F16: =IFERROR(VLOOKUP('18'!C16,'Items Servicios'!A:B,2,0),0) -> 0 | G16: =F16*D16 -> 0
A17: 6 | F17: =IFERROR(VLOOKUP('18'!C17,'Items Servicios'!A:B,2,0),0) -> 0 | G17: =F17*D17 -> 0
A18: ITEM | B18: Fecha | C18: SERVICIO NO TARIFADO | D18: CANTIDAD | E18: UNIDAD | F18: VALOR UNITARIO | G18: TOTAL | H18: TARIFAS E ITEMS DEBEN ESTAR AUTORIZADOS POR BANCO
A19: 7 | G19: =F19*D19 -> 0
A20: 8 | G20: =F20*D20 -> 0
A21: 9 | G21: =F21*D21 -> 0
A22: 10 | G22: =F22*D22 -> 0
A23: 11 | G23: =F23*D23 -> 0
D24: VALOR NETO DE SERVICIO | G24: =IFERROR(SUM(G12:G23),0) -> 0
A27: TODO SERVICIO DE CONTINUIDAD OPERATIVA DEBE CONTAR CON TICKET BCM, EL INFORME DEBE ESTAR SUBIDO A BCM
A29: SOPORTE APROBACION / AUTORIZACION

Sheet 19
A1: SERVICIO
A2: SOLICITANTE
A3: CATEGORÍA:
A4: ATM:
A5: NOMBRE:
A6: TICKET BCM
A7: OT
A8: TIPO DE MÁQUINA
A9: FECHA EJECUCION
A11: ITEM | B11: Fecha | C11: SERVICIO TARIFADO | D11: CANTIDAD | E11: UNIDAD | F11: VALOR UNITARIO | G11: TOTAL
A12: 1 | F12: =IFERROR(VLOOKUP('19'!C12,'Items Servicios'!A:B,2,0),0) -> 0 | G12: =F12*D12 -> 0
A13: 2 | F13: =IFERROR(VLOOKUP('19'!C13,'Items Servicios'!A:B,2,0),0) -> 0 | G13: =F13*D13 -> 0
A14: 3 | F14: =IFERROR(VLOOKUP('19'!C14,'Items Servicios'!A:B,2,0),0) -> 0 | G14: =F14*D14 -> 0
A15: 4 | F15: =IFERROR(VLOOKUP('19'!C15,'Items Servicios'!A:B,2,0),0) -> 0 | G15: =F15*D15 -> 0
A16: 5 | F16: =IFERROR(VLOOKUP('19'!C16,'Items Servicios'!A:B,2,0),0) -> 0 | G16: =F16*D16 -> 0
A17: 6 | F17: =IFERROR(VLOOKUP('19'!C17,'Items Servicios'!A:B,2,0),0) -> 0 | G17: =F17*D17 -> 0
A18: ITEM | B18: Fecha | C18: SERVICIO NO TARIFADO | D18: CANTIDAD | E18: UNIDAD | F18: VALOR UNITARIO | G18: TOTAL | H18: TARIFAS E ITEMS DEBEN ESTAR AUTORIZADOS POR BANCO
A19: 7 | G19: =F19*D19 -> 0
A20: 8 | G20: =F20*D20 -> 0
A21: 9 | G21: =F21*D21 -> 0
A22: 10 | G22: =F22*D22 -> 0
A23: 11 | G23: =F23*D23 -> 0
D24: VALOR NETO DE SERVICIO | G24: =IFERROR(SUM(G12:G23),0) -> 0
A27: TODO SERVICIO DE CONTINUIDAD OPERATIVA DEBE CONTAR CON TICKET BCM, EL INFORME DEBE ESTAR SUBIDO A BCM
A29: SOPORTE APROBACION / AUTORIZACION

Sheet 20
A1: SERVICIO
A2: SOLICITANTE
A3: CATEGORÍA:
A4: ATM:
A5: NOMBRE:
A6: TICKET BCM
A7: OT
A8: TIPO DE MÁQUINA
A9: FECHA EJECUCION
A11: ITEM | B11: Fecha | C11: SERVICIO TARIFADO | D11: CANTIDAD | E11: UNIDAD | F11: VALOR UNITARIO | G11: TOTAL
A12: 1 | F12: =IFERROR(VLOOKUP('20'!C12,'Items Servicios'!A:B,2,0),0) -> 0 | G12: =F12*D12 -> 0
A13: 2 | F13: =IFERROR(VLOOKUP('20'!C13,'Items Servicios'!A:B,2,0),0) -> 0 | G13: =F13*D13 -> 0
A14: 3 | F14: =IFERROR(VLOOKUP('20'!C14,'Items Servicios'!A:B,2,0),0) -> 0 | G14: =F14*D14 -> 0
A15: 4 | F15: =IFERROR(VLOOKUP('20'!C15,'Items Servicios'!A:B,2,0),0) -> 0 | G15: =F15*D15 -> 0
A16: 5 | F16: =IFERROR(VLOOKUP('20'!C16,'Items Servicios'!A:B,2,0),0) -> 0 | G16: =F16*D16 -> 0
A17: 6 | F17: =IFERROR(VLOOKUP('20'!C17,'Items Servicios'!A:B,2,0),0) -> 0 | G17: =F17*D17 -> 0
A18: ITEM | B18: Fecha | C18: SERVICIO NO TARIFADO | D18: CANTIDAD | E18: UNIDAD | F18: VALOR UNITARIO | G18: TOTAL | H18: TARIFAS E ITEMS DEBEN ESTAR AUTORIZADOS POR BANCO
A19: 7 | G19: =F19*D19 -> 0
A20: 8 | G20: =F20*D20 -> 0
A21: 9 | G21: =F21*D21 -> 0
A22: 10 | G22: =F22*D22 -> 0
A23: 11 | G23: =F23*D23 -> 0
D24: VALOR NETO DE SERVICIO | G24: =IFERROR(SUM(G12:G23),0) -> 0
A27: TODO SERVICIO DE CONTINUIDAD OPERATIVA DEBE CONTAR CON TICKET BCM, EL INFORME DEBE ESTAR SUBIDO A BCM
A29: SOPORTE APROBACION / AUTORIZACION

Sheet 21
A1: SERVICIO
A2: SOLICITANTE
A3: CATEGORÍA:
A4: ATM:
A5: NOMBRE:
A6: TICKET BCM
A7: OT
A8: TIPO DE MÁQUINA
A9: FECHA EJECUCION
A11: ITEM | B11: Fecha | C11: SERVICIO TARIFADO | D11: CANTIDAD | E11: UNIDAD | F11: VALOR UNITARIO | G11: TOTAL
A12: 1 | F12: =IFERROR(VLOOKUP('21'!C12,'Items Servicios'!A:B,2,0),0) -> 0 | G12: =F12*D12 -> 0
A13: 2 | F13: =IFERROR(VLOOKUP('21'!C13,'Items Servicios'!A:B,2,0),0) -> 0 | G13: =F13*D13 -> 0
A14: 3 | F14: =IFERROR(VLOOKUP('21'!C14,'Items Servicios'!A:B,2,0),0) -> 0 | G14: =F14*D14 -> 0
A15: 4 | F15: =IFERROR(VLOOKUP('21'!C15,'Items Servicios'!A:B,2,0),0) -> 0 | G15: =F15*D15 -> 0
A16: 5 | F16: =IFERROR(VLOOKUP('21'!C16,'Items Servicios'!A:B,2,0),0) -> 0 | G16: =F16*D16 -> 0
A17: 6 | F17: =IFERROR(VLOOKUP('21'!C17,'Items Servicios'!A:B,2,0),0) -> 0 | G17: =F17*D17 -> 0
A18: ITEM | B18: Fecha | C18: SERVICIO NO TARIFADO | D18: CANTIDAD | E18: UNIDAD | F18: VALOR UNITARIO | G18: TOTAL | H18: TARIFAS E ITEMS DEBEN ESTAR AUTORIZADOS POR BANCO
A19: 7 | G19: =F19*D19 -> 0
A20: 8 | G20: =F20*D20 -> 0
A21: 9 | G21: =F21*D21 -> 0
A22: 10 | G22: =F22*D22 -> 0
A23: 11 | G23: =F23*D23 -> 0
D24: VALOR NETO DE SERVICIO | G24: =IFERROR(SUM(G12:G23),0) -> 0
A27: TODO SERVICIO DE CONTINUIDAD OPERATIVA DEBE CONTAR CON TICKET BCM, EL INFORME DEBE ESTAR SUBIDO A BCM
A29: SOPORTE APROBACION / AUTORIZACION

Sheet 22
A1: SERVICIO
A2: SOLICITANTE
A3: CATEGORÍA:
A4: ATM:
A5: NOMBRE:
A6: TICKET BCM
A7: OT
A8: TIPO DE MÁQUINA
A9: FECHA EJECUCION
A11: ITEM | B11: Fecha | C11: SERVICIO TARIFADO | D11: CANTIDAD | E11: UNIDAD | F11: VALOR UNITARIO | G11: TOTAL
A12: 1 | F12: =IFERROR(VLOOKUP('22'!C12,'Items Servicios'!A:B,2,0),0) -> 0 | G12: =F12*D12 -> 0
A13: 2 | F13: =IFERROR(VLOOKUP('22'!C13,'Items Servicios'!A:B,2,0),0) -> 0 | G13: =F13*D13 -> 0
A14: 3 | F14: =IFERROR(VLOOKUP('22'!C14,'Items Servicios'!A:B,2,0),0) -> 0 | G14: =F14*D14 -> 0
A15: 4 | F15: =IFERROR(VLOOKUP('22'!C15,'Items Servicios'!A:B,2,0),0) -> 0 | G15: =F15*D15 -> 0
A16: 5 | F16: =IFERROR(VLOOKUP('22'!C16,'Items Servicios'!A:B,2,0),0) -> 0 | G16: =F16*D16 -> 0
A17: 6 | F17: =IFERROR(VLOOKUP('22'!C17,'Items Servicios'!A:B,2,0),0) -> 0 | G17: =F17*D17 -> 0
A18: ITEM | B18: Fecha | C18: SERVICIO NO TARIFADO | D18: CANTIDAD | E18: UNIDAD | F18: VALOR UNITARIO | G18: TOTAL | H18: TARIFAS E ITEMS DEBEN ESTAR AUTORIZADOS POR BANCO
A19: 7 | G19: =F19*D19 -> 0
A20: 8 | G20: =F20*D20 -> 0
A21: 9 | G21: =F21*D21 -> 0
A22: 10 | G22: =F22*D22 -> 0
A23: 11 | G23: =F23*D23 -> 0
D24: VALOR NETO DE SERVICIO | G24: =IFERROR(SUM(G12:G23),0) -> 0
A27: TODO SERVICIO DE CONTINUIDAD OPERATIVA DEBE CONTAR CON TICKET BCM, EL INFORME DEBE ESTAR SUBIDO A BCM
A29: SOPORTE APROBACION / AUTORIZACION

Sheet 23
A1: SERVICIO
A2: SOLICITANTE
A3: CATEGORÍA:
A4: ATM:
A5: NOMBRE:
A6: TICKET BCM
A7: OT
A8: TIPO DE MÁQUINA
A9: FECHA EJECUCION
A11: ITEM | B11: Fecha | C11: SERVICIO TARIFADO | D11: CANTIDAD | E11: UNIDAD | F11: VALOR UNITARIO | G11: TOTAL
A12: 1 | F12: =IFERROR(VLOOKUP('23'!C12,'Items Servicios'!A:B,2,0),0) -> 0 | G12: =F12*D12 -> 0
A13: 2 | F13: =IFERROR(VLOOKUP('23'!C13,'Items Servicios'!A:B,2,0),0) -> 0 | G13: =F13*D13 -> 0
A14: 3 | F14: =IFERROR(VLOOKUP('23'!C14,'Items Servicios'!A:B,2,0),0) -> 0 | G14: =F14*D14 -> 0
A15: 4 | F15: =IFERROR(VLOOKUP('23'!C15,'Items Servicios'!A:B,2,0),0) -> 0 | G15: =F15*D15 -> 0
A16: 5 | F16: =IFERROR(VLOOKUP('23'!C16,'Items Servicios'!A:B,2,0),0) -> 0 | G16: =F16*D16 -> 0
A17: 6 | F17: =IFERROR(VLOOKUP('23'!C17,'Items Servicios'!A:B,2,0),0) -> 0 | G17: =F17*D17 -> 0
A18: ITEM | B18: Fecha | C18: SERVICIO NO TARIFADO | D18: CANTIDAD | E18: UNIDAD | F18: VALOR UNITARIO | G18: TOTAL | H18: TARIFAS E ITEMS DEBEN ESTAR AUTORIZADOS POR BANCO
A19: 7 | G19: =F19*D19 -> 0
A20: 8 | G20: =F20*D20 -> 0
A21: 9 | G21: =F21*D21 -> 0
A22: 10 | G22: =F22*D22 -> 0
A23: 11 | G23: =F23*D23 -> 0
D24: VALOR NETO DE SERVICIO | G24: =IFERROR(SUM(G12:G23),0) -> 0
A27: TODO SERVICIO DE CONTINUIDAD OPERATIVA DEBE CONTAR CON TICKET BCM, EL INFORME DEBE ESTAR SUBIDO A BCM
A29: SOPORTE APROBACION / AUTORIZACION

Sheet 24
A1: SERVICIO
A2: SOLICITANTE
A3: CATEGORÍA:
A4: ATM:
A5: NOMBRE:
A6: TICKET BCM
A7: OT
A8: TIPO DE MÁQUINA
A9: FECHA EJECUCION
A11: ITEM | B11: Fecha | C11: SERVICIO TARIFADO | D11: CANTIDAD | E11: UNIDAD | F11: VALOR UNITARIO | G11: TOTAL
A12: 1 | F12: =IFERROR(VLOOKUP('24'!C12,'Items Servicios'!A:B,2,0),0) -> 0 | G12: =F12*D12 -> 0
A13: 2 | F13: =IFERROR(VLOOKUP('24'!C13,'Items Servicios'!A:B,2,0),0) -> 0 | G13: =F13*D13 -> 0
A14: 3 | F14: =IFERROR(VLOOKUP('24'!C14,'Items Servicios'!A:B,2,0),0) -> 0 | G14: =F14*D14 -> 0
A15: 4 | F15: =IFERROR(VLOOKUP('24'!C15,'Items Servicios'!A:B,2,0),0) -> 0 | G15: =F15*D15 -> 0
A16: 5 | F16: =IFERROR(VLOOKUP('24'!C16,'Items Servicios'!A:B,2,0),0) -> 0 | G16: =F16*D16 -> 0
A17: 6 | F17: =IFERROR(VLOOKUP('24'!C17,'Items Servicios'!A:B,2,0),0) -> 0 | G17: =F17*D17 -> 0
A18: ITEM | B18: Fecha | C18: SERVICIO NO TARIFADO | D18: CANTIDAD | E18: UNIDAD | F18: VALOR UNITARIO | G18: TOTAL | H18: TARIFAS E ITEMS DEBEN ESTAR AUTORIZADOS POR BANCO
A19: 7 | G19: =F19*D19 -> 0
A20: 8 | G20: =F20*D20 -> 0
A21: 9 | G21: =F21*D21 -> 0
A22: 10 | G22: =F22*D22 -> 0
A23: 11 | G23: =F23*D23 -> 0
D24: VALOR NETO DE SERVICIO | G24: =IFERROR(SUM(G12:G23),0) -> 0
A27: TODO SERVICIO DE CONTINUIDAD OPERATIVA DEBE CONTAR CON TICKET BCM, EL INFORME DEBE ESTAR SUBIDO A BCM
A29: SOPORTE APROBACION / AUTORIZACION

Sheet 25
A1: SERVICIO
A2: SOLICITANTE
A3: CATEGORÍA:
A4: ATM:
A5: NOMBRE:
A6: TICKET BCM
A7: OT
A8: TIPO DE MÁQUINA
A9: FECHA EJECUCION
A11: ITEM | B11: Fecha | C11: SERVICIO TARIFADO | D11: CANTIDAD | E11: UNIDAD | F11: VALOR UNITARIO | G11: TOTAL
A12: 1 | F12: =IFERROR(VLOOKUP('25'!C12,'Items Servicios'!A:B,2,0),0) -> 0 | G12: =F12*D12 -> 0
A13: 2 | F13: =IFERROR(VLOOKUP('25'!C13,'Items Servicios'!A:B,2,0),0) -> 0 | G13: =F13*D13 -> 0
A14: 3 | F14: =IFERROR(VLOOKUP('25'!C14,'Items Servicios'!A:B,2,0),0) -> 0 | G14: =F14*D14 -> 0
A15: 4 | F15: =IFERROR(VLOOKUP('25'!C15,'Items Servicios'!A:B,2,0),0) -> 0 | G15: =F15*D15 -> 0
A16: 5 | F16: =IFERROR(VLOOKUP('25'!C16,'Items Servicios'!A:B,2,0),0) -> 0 | G16: =F16*D16 -> 0
A17: 6 | F17: =IFERROR(VLOOKUP('25'!C17,'Items Servicios'!A:B,2,0),0) -> 0 | G17: =F17*D17 -> 0
A18: ITEM | B18: Fecha | C18: SERVICIO NO TARIFADO | D18: CANTIDAD | E18: UNIDAD | F18: VALOR UNITARIO | G18: TOTAL | H18: TARIFAS E ITEMS DEBEN ESTAR AUTORIZADOS POR BANCO
A19: 7 | G19: =F19*D19 -> 0
A20: 8 | G20: =F20*D20 -> 0
A21: 9 | G21: =F21*D21 -> 0
A22: 10 | G22: =F22*D22 -> 0
A23: 11 | G23: =F23*D23 -> 0
D24: VALOR NETO DE SERVICIO | G24: =IFERROR(SUM(G12:G23),0) -> 0
A27: TODO SERVICIO DE CONTINUIDAD OPERATIVA DEBE CONTAR CON TICKET BCM, EL INFORME DEBE ESTAR SUBIDO A BCM
A29: SOPORTE APROBACION / AUTORIZACION

Sheet 26
A1: SERVICIO
A2: SOLICITANTE
A3: CATEGORÍA:
A4: ATM:
A5: NOMBRE:
A6: TICKET BCM
A7: OT
A8: TIPO DE MÁQUINA
A9: FECHA EJECUCION
A11: ITEM | B11: Fecha | C11: SERVICIO TARIFADO | D11: CANTIDAD | E11: UNIDAD | F11: VALOR UNITARIO | G11: TOTAL
A12: 1 | F12: =IFERROR(VLOOKUP('26'!C12,'Items Servicios'!A:B,2,0),0) -> 0 | G12: =F12*D12 -> 0
A13: 2 | F13: =IFERROR(VLOOKUP('26'!C13,'Items Servicios'!A:B,2,0),0) -> 0 | G13: =F13*D13 -> 0
A14: 3 | F14: =IFERROR(VLOOKUP('26'!C14,'Items Servicios'!A:B,2,0),0) -> 0 | G14: =F14*D14 -> 0
A15: 4 | F15: =IFERROR(VLOOKUP('26'!C15,'Items Servicios'!A:B,2,0),0) -> 0 | G15: =F15*D15 -> 0
A16: 5 | F16: =IFERROR(VLOOKUP('26'!C16,'Items Servicios'!A:B,2,0),0) -> 0 | G16: =F16*D16 -> 0
A17: 6 | F17: =IFERROR(VLOOKUP('26'!C17,'Items Servicios'!A:B,2,0),0) -> 0 | G17: =F17*D17 -> 0
A18: ITEM | B18: Fecha | C18: SERVICIO NO TARIFADO | D18: CANTIDAD | E18: UNIDAD | F18: VALOR UNITARIO | G18: TOTAL | H18: TARIFAS E ITEMS DEBEN ESTAR AUTORIZADOS POR BANCO
A19: 7 | G19: =F19*D19 -> 0
A20: 8 | G20: =F20*D20 -> 0
A21: 9 | G21: =F21*D21 -> 0
A22: 10 | G22: =F22*D22 -> 0
A23: 11 | G23: =F23*D23 -> 0
D24: VALOR NETO DE SERVICIO | G24: =IFERROR(SUM(G12:G23),0) -> 0
A27: TODO SERVICIO DE CONTINUIDAD OPERATIVA DEBE CONTAR CON TICKET BCM, EL INFORME DEBE ESTAR SUBIDO A BCM
A29: SOPORTE APROBACION / AUTORIZACION

Sheet 27
A1: SERVICIO
A2: SOLICITANTE
A3: CATEGORÍA:
A4: ATM:
A5: NOMBRE:
A6: TICKET BCM
A7: OT
A8: TIPO DE MÁQUINA
A9: FECHA EJECUCION
A11: ITEM | B11: Fecha | C11: SERVICIO TARIFADO | D11: CANTIDAD | E11: UNIDAD | F11: VALOR UNITARIO | G11: TOTAL
A12: 1 | F12: =IFERROR(VLOOKUP('27'!C12,'Items Servicios'!A:B,2,0),0) -> 0 | G12: =F12*D12 -> 0
A13: 2 | F13: =IFERROR(VLOOKUP('27'!C13,'Items Servicios'!A:B,2,0),0) -> 0 | G13: =F13*D13 -> 0
A14: 3 | F14: =IFERROR(VLOOKUP('27'!C14,'Items Servicios'!A:B,2,0),0) -> 0 | G14: =F14*D14 -> 0
A15: 4 | F15: =IFERROR(VLOOKUP('27'!C15,'Items Servicios'!A:B,2,0),0) -> 0 | G15: =F15*D15 -> 0
A16: 5 | F16: =IFERROR(VLOOKUP('27'!C16,'Items Servicios'!A:B,2,0),0) -> 0 | G16: =F16*D16 -> 0
A17: 6 | F17: =IFERROR(VLOOKUP('27'!C17,'Items Servicios'!A:B,2,0),0) -> 0 | G17: =F17*D17 -> 0
A18: ITEM | B18: Fecha | C18: SERVICIO NO TARIFADO | D18: CANTIDAD | E18: UNIDAD | F18: VALOR UNITARIO | G18: TOTAL | H18: TARIFAS E ITEMS DEBEN ESTAR AUTORIZADOS POR BANCO
A19: 7 | G19: =F19*D19 -> 0
A20: 8 | G20: =F20*D20 -> 0
A21: 9 | G21: =F21*D21 -> 0
A22: 10 | G22: =F22*D22 -> 0
A23: 11 | G23: =F23*D23 -> 0
D24: VALOR NETO DE SERVICIO | G24: =IFERROR(SUM(G12:G23),0) -> 0
A27: TODO SERVICIO DE CONTINUIDAD OPERATIVA DEBE CONTAR CON TICKET BCM, EL INFORME DEBE ESTAR SUBIDO A BCM
A29: SOPORTE APROBACION / AUTORIZACION

Sheet 28
A1: SERVICIO
A2: SOLICITANTE
A3: CATEGORÍA:
A4: ATM:
A5: NOMBRE:
A6: TICKET BCM
A7: OT
A8: TIPO DE MÁQUINA
A9: FECHA EJECUCION
A11: ITEM | B11: Fecha | C11: SERVICIO TARIFADO | D11: CANTIDAD | E11: UNIDAD | F11: VALOR UNITARIO | G11: TOTAL
A12: 1 | F12: =IFERROR(VLOOKUP('28'!C12,'Items Servicios'!A:B,2,0),0) -> 0 | G12: =F12*D12 -> 0
A13: 2 | F13: =IFERROR(VLOOKUP('28'!C13,'Items Servicios'!A:B,2,0),0) -> 0 | G13: =F13*D13 -> 0
A14: 3 | F14: =IFERROR(VLOOKUP('28'!C14,'Items Servicios'!A:B,2,0),0) -> 0 | G14: =F14*D14 -> 0
A15: 4 | F15: =IFERROR(VLOOKUP('28'!C15,'Items Servicios'!A:B,2,0),0) -> 0 | G15: =F15*D15 -> 0
A16: 5 | F16: =IFERROR(VLOOKUP('28'!C16,'Items Servicios'!A:B,2,0),0) -> 0 | G16: =F16*D16 -> 0
A17: 6 | F17: =IFERROR(VLOOKUP('28'!C17,'Items Servicios'!A:B,2,0),0) -> 0 | G17: =F17*D17 -> 0
A18: ITEM | B18: Fecha | C18: SERVICIO NO TARIFADO | D18: CANTIDAD | E18: UNIDAD | F18: VALOR UNITARIO | G18: TOTAL | H18: TARIFAS E ITEMS DEBEN ESTAR AUTORIZADOS POR BANCO
A19: 7 | G19: =F19*D19 -> 0
A20: 8 | G20: =F20*D20 -> 0
A21: 9 | G21: =F21*D21 -> 0
A22: 10 | G22: =F22*D22 -> 0
A23: 11 | G23: =F23*D23 -> 0
D24: VALOR NETO DE SERVICIO | G24: =IFERROR(SUM(G12:G23),0) -> 0
A27: TODO SERVICIO DE CONTINUIDAD OPERATIVA DEBE CONTAR CON TICKET BCM, EL INFORME DEBE ESTAR SUBIDO A BCM
A29: SOPORTE APROBACION / AUTORIZACION

Sheet 29
A1: SERVICIO
A2: SOLICITANTE
A3: CATEGORÍA:
A4: ATM:
A5: NOMBRE:
A6: TICKET BCM
A7: OT
A8: TIPO DE MÁQUINA
A9: FECHA EJECUCION
A11: ITEM | B11: Fecha | C11: SERVICIO TARIFADO | D11: CANTIDAD | E11: UNIDAD | F11: VALOR UNITARIO | G11: TOTAL
A12: 1 | F12: =IFERROR(VLOOKUP('29'!C12,'Items Servicios'!A:B,2,0),0) -> 0 | G12: =F12*D12 -> 0
A13: 2 | F13: =IFERROR(VLOOKUP('29'!C13,'Items Servicios'!A:B,2,0),0) -> 0 | G13: =F13*D13 -> 0
A14: 3 | F14: =IFERROR(VLOOKUP('29'!C14,'Items Servicios'!A:B,2,0),0) -> 0 | G14: =F14*D14 -> 0
A15: 4 | F15: =IFERROR(VLOOKUP('29'!C15,'Items Servicios'!A:B,2,0),0) -> 0 | G15: =F15*D15 -> 0
A16: 5 | F16: =IFERROR(VLOOKUP('29'!C16,'Items Servicios'!A:B,2,0),0) -> 0 | G16: =F16*D16 -> 0
A17: 6 | F17: =IFERROR(VLOOKUP('29'!C17,'Items Servicios'!A:B,2,0),0) -> 0 | G17: =F17*D17 -> 0
A18: ITEM | B18: Fecha | C18: SERVICIO NO TARIFADO | D18: CANTIDAD | E18: UNIDAD | F18: VALOR UNITARIO | G18: TOTAL | H18: TARIFAS E ITEMS DEBEN ESTAR AUTORIZADOS POR BANCO
A19: 7 | G19: =F19*D19 -> 0
A20: 8 | G20: =F20*D20 -> 0
A21: 9 | G21: =F21*D21 -> 0
A22: 10 | G22: =F22*D22 -> 0
A23: 11 | G23: =F23*D23 -> 0
D24: VALOR NETO DE SERVICIO | G24: =IFERROR(SUM(G12:G23),0) -> 0
A27: TODO SERVICIO DE CONTINUIDAD OPERATIVA DEBE CONTAR CON TICKET BCM, EL INFORME DEBE ESTAR SUBIDO A BCM
A29: SOPORTE APROBACION / AUTORIZACION

Sheet 30
A1: SERVICIO
A2: SOLICITANTE
A3: CATEGORÍA:
A4: ATM:
A5: NOMBRE:
A6: TICKET BCM
A7: OT
A8: TIPO DE MÁQUINA
A9: FECHA EJECUCION
A11: ITEM | B11: Fecha | C11: SERVICIO TARIFADO | D11: CANTIDAD | E11: UNIDAD | F11: VALOR UNITARIO | G11: TOTAL
A12: 1 | F12: =IFERROR(VLOOKUP('30'!C12,'Items Servicios'!A:B,2,0),0) -> 0 | G12: =F12*D12 -> 0
A13: 2 | F13: =IFERROR(VLOOKUP('30'!C13,'Items Servicios'!A:B,2,0),0) -> 0 | G13: =F13*D13 -> 0
A14: 3 | F14: =IFERROR(VLOOKUP('30'!C14,'Items Servicios'!A:B,2,0),0) -> 0 | G14: =F14*D14 -> 0
A15: 4 | F15: =IFERROR(VLOOKUP('30'!C15,'Items Servicios'!A:B,2,0),0) -> 0 | G15: =F15*D15 -> 0
A16: 5 | F16: =IFERROR(VLOOKUP('30'!C16,'Items Servicios'!A:B,2,0),0) -> 0 | G16: =F16*D16 -> 0
A17: 6 | F17: =IFERROR(VLOOKUP('30'!C17,'Items Servicios'!A:B,2,0),0) -> 0 | G17: =F17*D17 -> 0
A18: ITEM | B18: Fecha | C18: SERVICIO NO TARIFADO | D18: CANTIDAD | E18: UNIDAD | F18: VALOR UNITARIO | G18: TOTAL | H18: TARIFAS E ITEMS DEBEN ESTAR AUTORIZADOS POR BANCO
A19: 7 | G19: =F19*D19 -> 0
A20: 8 | G20: =F20*D20 -> 0
A21: 9 | G21: =F21*D21 -> 0
A22: 10 | G22: =F22*D22 -> 0
A23: 11 | G23: =F23*D23 -> 0
D24: VALOR NETO DE SERVICIO | G24: =IFERROR(SUM(G12:G23),0) -> 0
A27: TODO SERVICIO DE CONTINUIDAD OPERATIVA DEBE CONTAR CON TICKET BCM, EL INFORME DEBE ESTAR SUBIDO A BCM
A29: SOPORTE APROBACION / AUTORIZACION

Sheet 31
A1: SERVICIO
A2: SOLICITANTE
A3: CATEGORÍA:
A4: ATM:
A5: NOMBRE:
A6: TICKET BCM
A7: OT
A8: TIPO DE MÁQUINA
A9: FECHA EJECUCION
A11: ITEM | B11: Fecha | C11: SERVICIO TARIFADO | D11: CANTIDAD | E11: UNIDAD | F11: VALOR UNITARIO | G11: TOTAL
A12: 1 | F12: =IFERROR(VLOOKUP('31'!C12,'Items Servicios'!A:B,2,0),0) -> 0 | G12: =F12*D12 -> 0
A13: 2 | F13: =IFERROR(VLOOKUP('31'!C13,'Items Servicios'!A:B,2,0),0) -> 0 | G13: =F13*D13 -> 0
A14: 3 | F14: =IFERROR(VLOOKUP('31'!C14,'Items Servicios'!A:B,2,0),0) -> 0 | G14: =F14*D14 -> 0
A15: 4 | F15: =IFERROR(VLOOKUP('31'!C15,'Items Servicios'!A:B,2,0),0) -> 0 | G15: =F15*D15 -> 0
A16: 5 | F16: =IFERROR(VLOOKUP('31'!C16,'Items Servicios'!A:B,2,0),0) -> 0 | G16: =F16*D16 -> 0
A17: 6 | F17: =IFERROR(VLOOKUP('31'!C17,'Items Servicios'!A:B,2,0),0) -> 0 | G17: =F17*D17 -> 0
A18: ITEM | B18: Fecha | C18: SERVICIO NO TARIFADO | D18: CANTIDAD | E18: UNIDAD | F18: VALOR UNITARIO | G18: TOTAL | H18: TARIFAS E ITEMS DEBEN ESTAR AUTORIZADOS POR BANCO
A19: 7 | G19: =F19*D19 -> 0
A20: 8 | G20: =F20*D20 -> 0
A21: 9 | G21: =F21*D21 -> 0
A22: 10 | G22: =F22*D22 -> 0
A23: 11 | G23: =F23*D23 -> 0
D24: VALOR NETO DE SERVICIO | G24: =IFERROR(SUM(G12:G23),0) -> 0
A27: TODO SERVICIO DE CONTINUIDAD OPERATIVA DEBE CONTAR CON TICKET BCM, EL INFORME DEBE ESTAR SUBIDO A BCM
A29: SOPORTE APROBACION / AUTORIZACION

Sheet 32
A1: SERVICIO
A2: SOLICITANTE
A3: CATEGORÍA:
A4: ATM:
A5: NOMBRE:
A6: TICKET BCM
A7: OT
A8: TIPO DE MÁQUINA
A9: FECHA EJECUCION
A11: ITEM | B11: Fecha | C11: SERVICIO TARIFADO | D11: CANTIDAD | E11: UNIDAD | F11: VALOR UNITARIO | G11: TOTAL
A12: 1 | F12: =IFERROR(VLOOKUP('32'!C12,'Items Servicios'!A:B,2,0),0) -> 0 | G12: =F12*D12 -> 0
A13: 2 | F13: =IFERROR(VLOOKUP('32'!C13,'Items Servicios'!A:B,2,0),0) -> 0 | G13: =F13*D13 -> 0
A14: 3 | F14: =IFERROR(VLOOKUP('32'!C14,'Items Servicios'!A:B,2,0),0) -> 0 | G14: =F14*D14 -> 0
A15: 4 | F15: =IFERROR(VLOOKUP('32'!C15,'Items Servicios'!A:B,2,0),0) -> 0 | G15: =F15*D15 -> 0
A16: 5 | F16: =IFERROR(VLOOKUP('32'!C16,'Items Servicios'!A:B,2,0),0) -> 0 | G16: =F16*D16 -> 0
A17: 6 | F17: =IFERROR(VLOOKUP('32'!C17,'Items Servicios'!A:B,2,0),0) -> 0 | G17: =F17*D17 -> 0
A18: ITEM | B18: Fecha | C18: SERVICIO NO TARIFADO | D18: CANTIDAD | E18: UNIDAD | F18: VALOR UNITARIO | G18: TOTAL | H18: TARIFAS E ITEMS DEBEN ESTAR AUTORIZADOS POR BANCO
A19: 7 | G19: =F19*D19 -> 0
A20: 8 | G20: =F20*D20 -> 0
A21: 9 | G21: =F21*D21 -> 0
A22: 10 | G22: =F22*D22 -> 0
A23: 11 | G23: =F23*D23 -> 0
D24: VALOR NETO DE SERVICIO | G24: =IFERROR(SUM(G12:G23),0) -> 0
A27: TODO SERVICIO DE CONTINUIDAD OPERATIVA DEBE CONTAR CON TICKET BCM, EL INFORME DEBE ESTAR SUBIDO A BCM
A29: SOPORTE APROBACION / AUTORIZACION

Sheet 33
A1: SERVICIO
A2: SOLICITANTE
A3: CATEGORÍA:
A4: ATM:
A5: NOMBRE:
A6: TICKET BCM
A7: OT
A8: TIPO DE MÁQUINA
A9: FECHA EJECUCION
A11: ITEM | B11: Fecha | C11: SERVICIO TARIFADO | D11: CANTIDAD | E11: UNIDAD | F11: VALOR UNITARIO | G11: TOTAL
A12: 1 | F12: =IFERROR(VLOOKUP('33'!C12,'Items Servicios'!A:B,2,0),0) -> 0 | G12: =F12*D12 -> 0
A13: 2 | F13: =IFERROR(VLOOKUP('33'!C13,'Items Servicios'!A:B,2,0),0) -> 0 | G13: =F13*D13 -> 0
A14: 3 | F14: =IFERROR(VLOOKUP('33'!C14,'Items Servicios'!A:B,2,0),0) -> 0 | G14: =F14*D14 -> 0
A15: 4 | F15: =IFERROR(VLOOKUP('33'!C15,'Items Servicios'!A:B,2,0),0) -> 0 | G15: =F15*D15 -> 0
A16: 5 | F16: =IFERROR(VLOOKUP('33'!C16,'Items Servicios'!A:B,2,0),0) -> 0 | G16: =F16*D16 -> 0
A17: 6 | F17: =IFERROR(VLOOKUP('33'!C17,'Items Servicios'!A:B,2,0),0) -> 0 | G17: =F17*D17 -> 0
A18: ITEM | B18: Fecha | C18: SERVICIO NO TARIFADO | D18: CANTIDAD | E18: UNIDAD | F18: VALOR UNITARIO | G18: TOTAL | H18: TARIFAS E ITEMS DEBEN ESTAR AUTORIZADOS POR BANCO
A19: 7 | G19: =F19*D19 -> 0
A20: 8 | G20: =F20*D20 -> 0
A21: 9 | G21: =F21*D21 -> 0
A22: 10 | G22: =F22*D22 -> 0
A23: 11 | G23: =F23*D23 -> 0
D24: VALOR NETO DE SERVICIO | G24: =IFERROR(SUM(G12:G23),0) -> 0
A27: TODO SERVICIO DE CONTINUIDAD OPERATIVA DEBE CONTAR CON TICKET BCM, EL INFORME DEBE ESTAR SUBIDO A BCM
A29: SOPORTE APROBACION / AUTORIZACION

Sheet 34
A1: SERVICIO
A2: SOLICITANTE
A3: CATEGORÍA:
A4: ATM:
A5: NOMBRE:
A6: TICKET BCM
A7: OT
A8: TIPO DE MÁQUINA
A9: FECHA EJECUCION
A11: ITEM | B11: Fecha | C11: SERVICIO TARIFADO | D11: CANTIDAD | E11: UNIDAD | F11: VALOR UNITARIO | G11: TOTAL
A12: 1 | F12: =IFERROR(VLOOKUP('34'!C12,'Items Servicios'!A:B,2,0),0) -> 0 | G12: =F12*D12 -> 0
A13: 2 | F13: =IFERROR(VLOOKUP('34'!C13,'Items Servicios'!A:B,2,0),0) -> 0 | G13: =F13*D13 -> 0
A14: 3 | F14: =IFERROR(VLOOKUP('34'!C14,'Items Servicios'!A:B,2,0),0) -> 0 | G14: =F14*D14 -> 0
A15: 4 | F15: =IFERROR(VLOOKUP('34'!C15,'Items Servicios'!A:B,2,0),0) -> 0 | G15: =F15*D15 -> 0
A16: 5 | F16: =IFERROR(VLOOKUP('34'!C16,'Items Servicios'!A:B,2,0),0) -> 0 | G16: =F16*D16 -> 0
A17: 6 | F17: =IFERROR(VLOOKUP('34'!C17,'Items Servicios'!A:B,2,0),0) -> 0 | G17: =F17*D17 -> 0
A18: ITEM | B18: Fecha | C18: SERVICIO NO TARIFADO | D18: CANTIDAD | E18: UNIDAD | F18: VALOR UNITARIO | G18: TOTAL | H18: TARIFAS E ITEMS DEBEN ESTAR AUTORIZADOS POR BANCO
A19: 7 | G19: =F19*D19 -> 0
A20: 8 | G20: =F20*D20 -> 0
A21: 9 | G21: =F21*D21 -> 0
A22: 10 | G22: =F22*D22 -> 0
A23: 11 | G23: =F23*D23 -> 0
D24: VALOR NETO DE SERVICIO | G24: =IFERROR(SUM(G12:G23),0) -> 0
A27: TODO SERVICIO DE CONTINUIDAD OPERATIVA DEBE CONTAR CON TICKET BCM, EL INFORME DEBE ESTAR SUBIDO A BCM
A29: SOPORTE APROBACION / AUTORIZACION

Sheet 35
A1: SERVICIO
A2: SOLICITANTE
A3: CATEGORÍA:
A4: ATM:
A5: NOMBRE:
A6: TICKET BCM
A7: OT
A8: TIPO DE MÁQUINA
A9: FECHA EJECUCION
A11: ITEM | B11: Fecha | C11: SERVICIO TARIFADO | D11: CANTIDAD | E11: UNIDAD | F11: VALOR UNITARIO | G11: TOTAL
A12: 1 | F12: =IFERROR(VLOOKUP('35'!C12,'Items Servicios'!A:B,2,0),0) -> 0 | G12: =F12*D12 -> 0
A13: 2 | F13: =IFERROR(VLOOKUP('35'!C13,'Items Servicios'!A:B,2,0),0) -> 0 | G13: =F13*D13 -> 0
A14: 3 | F14: =IFERROR(VLOOKUP('35'!C14,'Items Servicios'!A:B,2,0),0) -> 0 | G14: =F14*D14 -> 0
A15: 4 | F15: =IFERROR(VLOOKUP('35'!C15,'Items Servicios'!A:B,2,0),0) -> 0 | G15: =F15*D15 -> 0
A16: 5 | F16: =IFERROR(VLOOKUP('35'!C16,'Items Servicios'!A:B,2,0),0) -> 0 | G16: =F16*D16 -> 0
A17: 6 | F17: =IFERROR(VLOOKUP('35'!C17,'Items Servicios'!A:B,2,0),0) -> 0 | G17: =F17*D17 -> 0
A18: ITEM | B18: Fecha | C18: SERVICIO NO TARIFADO | D18: CANTIDAD | E18: UNIDAD | F18: VALOR UNITARIO | G18: TOTAL | H18: TARIFAS E ITEMS DEBEN ESTAR AUTORIZADOS POR BANCO
A19: 7 | G19: =F19*D19 -> 0
A20: 8 | G20: =F20*D20 -> 0
A21: 9 | G21: =F21*D21 -> 0
A22: 10 | G22: =F22*D22 -> 0
A23: 11 | G23: =F23*D23 -> 0
D24: VALOR NETO DE SERVICIO | G24: =IFERROR(SUM(G12:G23),0) -> 0
A27: TODO SERVICIO DE CONTINUIDAD OPERATIVA DEBE CONTAR CON TICKET BCM, EL INFORME DEBE ESTAR SUBIDO A BCM
A29: SOPORTE APROBACION / AUTORIZACION

Sheet 36
A1: SERVICIO
A2: SOLICITANTE
A3: CATEGORÍA:
A4: ATM:
A5: NOMBRE:
A6: TICKET BCM
A7: OT
A8: TIPO DE MÁQUINA
A9: FECHA EJECUCION
A11: ITEM | B11: Fecha | C11: SERVICIO TARIFADO | D11: CANTIDAD | E11: UNIDAD | F11: VALOR UNITARIO | G11: TOTAL
A12: 1 | F12: =IFERROR(VLOOKUP('36'!C12,'Items Servicios'!A:B,2,0),0) -> 0 | G12: =F12*D12 -> 0
A13: 2 | F13: =IFERROR(VLOOKUP('36'!C13,'Items Servicios'!A:B,2,0),0) -> 0 | G13: =F13*D13 -> 0
A14: 3 | F14: =IFERROR(VLOOKUP('36'!C14,'Items Servicios'!A:B,2,0),0) -> 0 | G14: =F14*D14 -> 0
A15: 4 | F15: =IFERROR(VLOOKUP('36'!C15,'Items Servicios'!A:B,2,0),0) -> 0 | G15: =F15*D15 -> 0
A16: 5 | F16: =IFERROR(VLOOKUP('36'!C16,'Items Servicios'!A:B,2,0),0) -> 0 | G16: =F16*D16 -> 0
A17: 6 | F17: =IFERROR(VLOOKUP('36'!C17,'Items Servicios'!A:B,2,0),0) -> 0 | G17: =F17*D17 -> 0
A18: ITEM | B18: Fecha | C18: SERVICIO NO TARIFADO | D18: CANTIDAD | E18: UNIDAD | F18: VALOR UNITARIO | G18: TOTAL | H18: TARIFAS E ITEMS DEBEN ESTAR AUTORIZADOS POR BANCO
A19: 7 | G19: =F19*D19 -> 0
A20: 8 | G20: =F20*D20 -> 0
A21: 9 | G21: =F21*D21 -> 0
A22: 10 | G22: =F22*D22 -> 0
A23: 11 | G23: =F23*D23 -> 0
D24: VALOR NETO DE SERVICIO | G24: =IFERROR(SUM(G12:G23),0) -> 0
A27: TODO SERVICIO DE CONTINUIDAD OPERATIVA DEBE CONTAR CON TICKET BCM, EL INFORME DEBE ESTAR SUBIDO A BCM
A29: SOPORTE APROBACION / AUTORIZACION

Sheet 37
A1: SERVICIO
A2: SOLICITANTE
A3: CATEGORÍA:
A4: ATM:
A5: NOMBRE:
A6: TICKET BCM
A7: OT
A8: TIPO DE MÁQUINA
A9: FECHA EJECUCION
A11: ITEM | B11: Fecha | C11: SERVICIO TARIFADO | D11: CANTIDAD | E11: UNIDAD | F11: VALOR UNITARIO | G11: TOTAL
A12: 1 | F12: =IFERROR(VLOOKUP('37'!C12,'Items Servicios'!A:B,2,0),0) -> 0 | G12: =F12*D12 -> 0
A13: 2 | F13: =IFERROR(VLOOKUP('37'!C13,'Items Servicios'!A:B,2,0),0) -> 0 | G13: =F13*D13 -> 0
A14: 3 | F14: =IFERROR(VLOOKUP('37'!C14,'Items Servicios'!A:B,2,0),0) -> 0 | G14: =F14*D14 -> 0
A15: 4 | F15: =IFERROR(VLOOKUP('37'!C15,'Items Servicios'!A:B,2,0),0) -> 0 | G15: =F15*D15 -> 0
A16: 5 | F16: =IFERROR(VLOOKUP('37'!C16,'Items Servicios'!A:B,2,0),0) -> 0 | G16: =F16*D16 -> 0
A17: 6 | F17: =IFERROR(VLOOKUP('37'!C17,'Items Servicios'!A:B,2,0),0) -> 0 | G17: =F17*D17 -> 0
A18: ITEM | B18: Fecha | C18: SERVICIO NO TARIFADO | D18: CANTIDAD | E18: UNIDAD | F18: VALOR UNITARIO | G18: TOTAL | H18: TARIFAS E ITEMS DEBEN ESTAR AUTORIZADOS POR BANCO
A19: 7 | G19: =F19*D19 -> 0
A20: 8 | G20: =F20*D20 -> 0
A21: 9 | G21: =F21*D21 -> 0
A22: 10 | G22: =F22*D22 -> 0
A23: 11 | G23: =F23*D23 -> 0
D24: VALOR NETO DE SERVICIO | G24: =IFERROR(SUM(G12:G23),0) -> 0
A27: TODO SERVICIO DE CONTINUIDAD OPERATIVA DEBE CONTAR CON TICKET BCM, EL INFORME DEBE ESTAR SUBIDO A BCM
A29: SOPORTE APROBACION / AUTORIZACION

Sheet 38
A1: SERVICIO
A2: SOLICITANTE
A3: CATEGORÍA:
A4: ATM:
A5: NOMBRE:
A6: TICKET BCM
A7: OT
A8: TIPO DE MÁQUINA
A9: FECHA EJECUCION
A11: ITEM | B11: Fecha | C11: SERVICIO TARIFADO | D11: CANTIDAD | E11: UNIDAD | F11: VALOR UNITARIO | G11: TOTAL
A12: 1 | F12: =IFERROR(VLOOKUP('38'!C12,'Items Servicios'!A:B,2,0),0) -> 0 | G12: =F12*D12 -> 0
A13: 2 | F13: =IFERROR(VLOOKUP('38'!C13,'Items Servicios'!A:B,2,0),0) -> 0 | G13: =F13*D13 -> 0
A14: 3 | F14: =IFERROR(VLOOKUP('38'!C14,'Items Servicios'!A:B,2,0),0) -> 0 | G14: =F14*D14 -> 0
A15: 4 | F15: =IFERROR(VLOOKUP('38'!C15,'Items Servicios'!A:B,2,0),0) -> 0 | G15: =F15*D15 -> 0
A16: 5 | F16: =IFERROR(VLOOKUP('38'!C16,'Items Servicios'!A:B,2,0),0) -> 0 | G16: =F16*D16 -> 0
A17: 6 | F17: =IFERROR(VLOOKUP('38'!C17,'Items Servicios'!A:B,2,0),0) -> 0 | G17: =F17*D17 -> 0
A18: ITEM | B18: Fecha | C18: SERVICIO NO TARIFADO | D18: CANTIDAD | E18: UNIDAD | F18: VALOR UNITARIO | G18: TOTAL | H18: TARIFAS E ITEMS DEBEN ESTAR AUTORIZADOS POR BANCO
A19: 7 | G19: =F19*D19 -> 0
A20: 8 | G20: =F20*D20 -> 0
A21: 9 | G21: =F21*D21 -> 0
A22: 10 | G22: =F22*D22 -> 0
A23: 11 | G23: =F23*D23 -> 0
D24: VALOR NETO DE SERVICIO | G24: =IFERROR(SUM(G12:G23),0) -> 0
A27: TODO SERVICIO DE CONTINUIDAD OPERATIVA DEBE CONTAR CON TICKET BCM, EL INFORME DEBE ESTAR SUBIDO A BCM
A29: SOPORTE APROBACION / AUTORIZACION

Sheet 39
A1: SERVICIO
A2: SOLICITANTE
A3: CATEGORÍA:
A4: ATM:
A5: NOMBRE:
A6: TICKET BCM
A7: OT
A8: TIPO DE MÁQUINA
A9: FECHA EJECUCION
A11: ITEM | B11: Fecha | C11: SERVICIO TARIFADO | D11: CANTIDAD | E11: UNIDAD | F11: VALOR UNITARIO | G11: TOTAL
A12: 1 | F12: =IFERROR(VLOOKUP('39'!C12,'Items Servicios'!A:B,2,0),0) -> 0 | G12: =F12*D12 -> 0
A13: 2 | F13: =IFERROR(VLOOKUP('39'!C13,'Items Servicios'!A:B,2,0),0) -> 0 | G13: =F13*D13 -> 0
A14: 3 | F14: =IFERROR(VLOOKUP('39'!C14,'Items Servicios'!A:B,2,0),0) -> 0 | G14: =F14*D14 -> 0
A15: 4 | F15: =IFERROR(VLOOKUP('39'!C15,'Items Servicios'!A:B,2,0),0) -> 0 | G15: =F15*D15 -> 0
A16: 5 | F16: =IFERROR(VLOOKUP('39'!C16,'Items Servicios'!A:B,2,0),0) -> 0 | G16: =F16*D16 -> 0
A17: 6 | F17: =IFERROR(VLOOKUP('39'!C17,'Items Servicios'!A:B,2,0),0) -> 0 | G17: =F17*D17 -> 0
A18: ITEM | B18: Fecha | C18: SERVICIO NO TARIFADO | D18: CANTIDAD | E18: UNIDAD | F18: VALOR UNITARIO | G18: TOTAL | H18: TARIFAS E ITEMS DEBEN ESTAR AUTORIZADOS POR BANCO
A19: 7 | G19: =F19*D19 -> 0
A20: 8 | G20: =F20*D20 -> 0
A21: 9 | G21: =F21*D21 -> 0
A22: 10 | G22: =F22*D22 -> 0
A23: 11 | G23: =F23*D23 -> 0
D24: VALOR NETO DE SERVICIO | G24: =IFERROR(SUM(G12:G23),0) -> 0
A27: TODO SERVICIO DE CONTINUIDAD OPERATIVA DEBE CONTAR CON TICKET BCM, EL INFORME DEBE ESTAR SUBIDO A BCM
A29: SOPORTE APROBACION / AUTORIZACION

Sheet 40
A1: SERVICIO
A2: SOLICITANTE
A3: CATEGORÍA:
A4: ATM:
A5: NOMBRE:
A6: TICKET BCM
A7: OT
A8: TIPO DE MÁQUINA
A9: FECHA EJECUCION
A11: ITEM | B11: Fecha | C11: SERVICIO TARIFADO | D11: CANTIDAD | E11: UNIDAD | F11: VALOR UNITARIO | G11: TOTAL
A12: 1 | F12: =IFERROR(VLOOKUP('40'!C12,'Items Servicios'!A:B,2,0),0) -> 0 | G12: =F12*D12 -> 0
A13: 2 | F13: =IFERROR(VLOOKUP('40'!C13,'Items Servicios'!A:B,2,0),0) -> 0 | G13: =F13*D13 -> 0
A14: 3 | F14: =IFERROR(VLOOKUP('40'!C14,'Items Servicios'!A:B,2,0),0) -> 0 | G14: =F14*D14 -> 0
A15: 4 | F15: =IFERROR(VLOOKUP('40'!C15,'Items Servicios'!A:B,2,0),0) -> 0 | G15: =F15*D15 -> 0
